[2025-08-24T18:10:41.663+0100] {local_task_job_runner.py:120} INFO - ::group::Pre task execution logs
[2025-08-24T18:10:41.670+0100] {taskinstance.py:2076} INFO - Dependencies all met for dep_context=non-requeueable deps ti=<TaskInstance: churn_pipeline_taskflow.ingestion manual__2025-08-24T17:10:05.661691+00:00 [queued]>
[2025-08-24T18:10:41.672+0100] {taskinstance.py:2076} INFO - Dependencies all met for dep_context=requeueable deps ti=<TaskInstance: churn_pipeline_taskflow.ingestion manual__2025-08-24T17:10:05.661691+00:00 [queued]>
[2025-08-24T18:10:41.672+0100] {taskinstance.py:2306} INFO - Starting attempt 4 of 6
[2025-08-24T18:10:41.676+0100] {taskinstance.py:2330} INFO - Executing <Task(_PythonDecoratedOperator): ingestion> on 2025-08-24 17:10:05.661691+00:00
[2025-08-24T18:10:41.678+0100] {standard_task_runner.py:64} INFO - Started process 26252 to run task
[2025-08-24T18:10:41.681+0100] {standard_task_runner.py:90} INFO - Running: ['airflow', 'tasks', 'run', 'churn_pipeline_taskflow', 'ingestion', 'manual__2025-08-24T17:10:05.661691+00:00', '--job-id', '24', '--raw', '--subdir', 'DAGS_FOLDER/.ipynb_checkpoints/airflow_dag-checkpoint.py', '--cfg-path', '/var/folders/c_/hn2ql5p54ylf2dsc72vqg5h40000gn/T/tmpzf_0as5n']
[2025-08-24T18:10:41.682+0100] {standard_task_runner.py:91} INFO - Job 24: Subtask ingestion
[2025-08-24T18:10:41.695+0100] {task_command.py:426} INFO - Running <TaskInstance: churn_pipeline_taskflow.ingestion manual__2025-08-24T17:10:05.661691+00:00 [running]> on host mac.communityfibre.co.uk
[2025-08-24T18:10:41.715+0100] {taskinstance.py:2648} INFO - Exporting env vars: AIRFLOW_CTX_DAG_OWNER='shivam' AIRFLOW_CTX_DAG_ID='churn_pipeline_taskflow' AIRFLOW_CTX_TASK_ID='ingestion' AIRFLOW_CTX_EXECUTION_DATE='2025-08-24T17:10:05.661691+00:00' AIRFLOW_CTX_TRY_NUMBER='4' AIRFLOW_CTX_DAG_RUN_ID='manual__2025-08-24T17:10:05.661691+00:00'
[2025-08-24T18:10:41.715+0100] {taskinstance.py:430} INFO - ::endgroup::
[2025-08-24T18:10:44.793+0100] {taskinstance.py:441} INFO - ::group::Post task execution logs
[2025-08-24T18:10:44.794+0100] {taskinstance.py:2905} ERROR - Task failed with exception
Traceback (most recent call last):
  File "/Users/homeaccount/miniconda3/envs/churn_pipeline/lib/python3.10/site-packages/airflow/models/taskinstance.py", line 465, in _execute_task
    result = _execute_callable(context=context, **execute_callable_kwargs)
  File "/Users/homeaccount/miniconda3/envs/churn_pipeline/lib/python3.10/site-packages/airflow/models/taskinstance.py", line 432, in _execute_callable
    return execute_callable(context=context, **execute_callable_kwargs)
  File "/Users/homeaccount/miniconda3/envs/churn_pipeline/lib/python3.10/site-packages/airflow/models/baseoperator.py", line 401, in wrapper
    return func(self, *args, **kwargs)
  File "/Users/homeaccount/miniconda3/envs/churn_pipeline/lib/python3.10/site-packages/airflow/decorators/base.py", line 265, in execute
    return_value = super().execute(context)
  File "/Users/homeaccount/miniconda3/envs/churn_pipeline/lib/python3.10/site-packages/airflow/models/baseoperator.py", line 401, in wrapper
    return func(self, *args, **kwargs)
  File "/Users/homeaccount/miniconda3/envs/churn_pipeline/lib/python3.10/site-packages/airflow/operators/python.py", line 235, in execute
    return_value = self.execute_callable()
  File "/Users/homeaccount/miniconda3/envs/churn_pipeline/lib/python3.10/site-packages/airflow/operators/python.py", line 252, in execute_callable
    return self.python_callable(*self.op_args, **self.op_kwargs)
  File "/Users/homeaccount/PycharmProjects/dmml/churn_prediction_pipeline/airflow_home/dags/.ipynb_checkpoints/airflow_dag-checkpoint.py", line 30, in ingestion
    run_cmd(["dvc", "add", "data/raw/telco_churn.csv", "data/raw/hf_bank_customer_support.csv"])
  File "/Users/homeaccount/PycharmProjects/dmml/churn_prediction_pipeline/airflow_home/dags/.ipynb_checkpoints/airflow_dag-checkpoint.py", line 16, in run_cmd
    subprocess.run(cmd, check=True)
  File "/Users/homeaccount/miniconda3/envs/churn_pipeline/lib/python3.10/subprocess.py", line 526, in run
    raise CalledProcessError(retcode, process.args,
subprocess.CalledProcessError: Command '['dvc', 'add', 'data/raw/telco_churn.csv', 'data/raw/hf_bank_customer_support.csv']' returned non-zero exit status 1.
[2025-08-24T18:10:44.798+0100] {taskinstance.py:1206} INFO - Marking task as UP_FOR_RETRY. dag_id=churn_pipeline_taskflow, task_id=ingestion, run_id=manual__2025-08-24T17:10:05.661691+00:00, execution_date=20250824T171005, start_date=20250824T171041, end_date=20250824T171044
[2025-08-24T18:10:44.802+0100] {standard_task_runner.py:110} ERROR - Failed to execute job 24 for task ingestion (Command '['dvc', 'add', 'data/raw/telco_churn.csv', 'data/raw/hf_bank_customer_support.csv']' returned non-zero exit status 1.; 26252)
[2025-08-24T18:10:44.815+0100] {local_task_job_runner.py:243} INFO - Task exited with return code 1
[2025-08-24T18:10:44.823+0100] {taskinstance.py:3503} INFO - 0 downstream tasks scheduled from follow-on schedule check
[2025-08-24T18:10:44.823+0100] {local_task_job_runner.py:222} INFO - ::endgroup::
