[2025-08-24T18:14:28.401+0100] {local_task_job_runner.py:120} INFO - ::group::Pre task execution logs
[2025-08-24T18:14:28.408+0100] {taskinstance.py:2076} INFO - Dependencies all met for dep_context=non-requeueable deps ti=<TaskInstance: churn_pipeline_taskflow.ingestion manual__2025-08-24T17:13:36.761059+00:00 [queued]>
[2025-08-24T18:14:28.410+0100] {taskinstance.py:2076} INFO - Dependencies all met for dep_context=requeueable deps ti=<TaskInstance: churn_pipeline_taskflow.ingestion manual__2025-08-24T17:13:36.761059+00:00 [queued]>
[2025-08-24T18:14:28.410+0100] {taskinstance.py:2306} INFO - Starting attempt 6 of 6
[2025-08-24T18:14:28.413+0100] {taskinstance.py:2330} INFO - Executing <Task(_PythonDecoratedOperator): ingestion> on 2025-08-24 17:13:36.761059+00:00
[2025-08-24T18:14:28.415+0100] {standard_task_runner.py:64} INFO - Started process 26388 to run task
[2025-08-24T18:14:28.418+0100] {standard_task_runner.py:90} INFO - Running: ['airflow', 'tasks', 'run', 'churn_pipeline_taskflow', 'ingestion', 'manual__2025-08-24T17:13:36.761059+00:00', '--job-id', '28', '--raw', '--subdir', 'DAGS_FOLDER/.ipynb_checkpoints/airflow_dag-checkpoint.py', '--cfg-path', '/var/folders/c_/hn2ql5p54ylf2dsc72vqg5h40000gn/T/tmpsqs14lsh']
[2025-08-24T18:14:28.419+0100] {standard_task_runner.py:91} INFO - Job 28: Subtask ingestion
[2025-08-24T18:14:28.432+0100] {task_command.py:426} INFO - Running <TaskInstance: churn_pipeline_taskflow.ingestion manual__2025-08-24T17:13:36.761059+00:00 [running]> on host mac.communityfibre.co.uk
[2025-08-24T18:14:28.452+0100] {taskinstance.py:2648} INFO - Exporting env vars: AIRFLOW_CTX_DAG_OWNER='shivam' AIRFLOW_CTX_DAG_ID='churn_pipeline_taskflow' AIRFLOW_CTX_TASK_ID='ingestion' AIRFLOW_CTX_EXECUTION_DATE='2025-08-24T17:13:36.761059+00:00' AIRFLOW_CTX_TRY_NUMBER='6' AIRFLOW_CTX_DAG_RUN_ID='manual__2025-08-24T17:13:36.761059+00:00'
[2025-08-24T18:14:28.452+0100] {taskinstance.py:430} INFO - ::endgroup::
[2025-08-24T18:14:28.452+0100] {logging_mixin.py:188} INFO - /Users/homeaccount/PycharmProjects/dmml/churn_prediction_pipeline
[2025-08-24T18:14:31.424+0100] {taskinstance.py:441} INFO - ::group::Post task execution logs
[2025-08-24T18:14:31.424+0100] {taskinstance.py:2905} ERROR - Task failed with exception
Traceback (most recent call last):
  File "/Users/homeaccount/miniconda3/envs/churn_pipeline/lib/python3.10/site-packages/airflow/models/taskinstance.py", line 465, in _execute_task
    result = _execute_callable(context=context, **execute_callable_kwargs)
  File "/Users/homeaccount/miniconda3/envs/churn_pipeline/lib/python3.10/site-packages/airflow/models/taskinstance.py", line 432, in _execute_callable
    return execute_callable(context=context, **execute_callable_kwargs)
  File "/Users/homeaccount/miniconda3/envs/churn_pipeline/lib/python3.10/site-packages/airflow/models/baseoperator.py", line 401, in wrapper
    return func(self, *args, **kwargs)
  File "/Users/homeaccount/miniconda3/envs/churn_pipeline/lib/python3.10/site-packages/airflow/decorators/base.py", line 265, in execute
    return_value = super().execute(context)
  File "/Users/homeaccount/miniconda3/envs/churn_pipeline/lib/python3.10/site-packages/airflow/models/baseoperator.py", line 401, in wrapper
    return func(self, *args, **kwargs)
  File "/Users/homeaccount/miniconda3/envs/churn_pipeline/lib/python3.10/site-packages/airflow/operators/python.py", line 235, in execute
    return_value = self.execute_callable()
  File "/Users/homeaccount/miniconda3/envs/churn_pipeline/lib/python3.10/site-packages/airflow/operators/python.py", line 252, in execute_callable
    return self.python_callable(*self.op_args, **self.op_kwargs)
  File "/Users/homeaccount/PycharmProjects/dmml/churn_prediction_pipeline/airflow_home/dags/.ipynb_checkpoints/airflow_dag-checkpoint.py", line 31, in ingestion
    run_cmd(["dvc", "add", "data/raw/telco_churn.csv", "data/raw/hf_bank_customer_support.csv"])
  File "/Users/homeaccount/PycharmProjects/dmml/churn_prediction_pipeline/airflow_home/dags/.ipynb_checkpoints/airflow_dag-checkpoint.py", line 16, in run_cmd
    subprocess.run(cmd, check=True)
  File "/Users/homeaccount/miniconda3/envs/churn_pipeline/lib/python3.10/subprocess.py", line 526, in run
    raise CalledProcessError(retcode, process.args,
subprocess.CalledProcessError: Command '['dvc', 'add', 'data/raw/telco_churn.csv', 'data/raw/hf_bank_customer_support.csv']' returned non-zero exit status 1.
[2025-08-24T18:14:31.427+0100] {taskinstance.py:1206} INFO - Marking task as FAILED. dag_id=churn_pipeline_taskflow, task_id=ingestion, run_id=manual__2025-08-24T17:13:36.761059+00:00, execution_date=20250824T171336, start_date=20250824T171428, end_date=20250824T171431
[2025-08-24T18:14:31.431+0100] {standard_task_runner.py:110} ERROR - Failed to execute job 28 for task ingestion (Command '['dvc', 'add', 'data/raw/telco_churn.csv', 'data/raw/hf_bank_customer_support.csv']' returned non-zero exit status 1.; 26388)
[2025-08-24T18:14:31.453+0100] {local_task_job_runner.py:243} INFO - Task exited with return code 1
[2025-08-24T18:14:31.460+0100] {taskinstance.py:3503} INFO - 0 downstream tasks scheduled from follow-on schedule check
[2025-08-24T18:14:31.461+0100] {local_task_job_runner.py:222} INFO - ::endgroup::
