[2025-08-24T17:41:46.069+0100] {local_task_job_runner.py:120} INFO - ::group::Pre task execution logs
[2025-08-24T17:41:46.077+0100] {taskinstance.py:2076} INFO - Dependencies all met for dep_context=non-requeueable deps ti=<TaskInstance: churn_pipeline_taskflow.ingestion scheduled__2025-08-22T23:00:00+00:00 [queued]>
[2025-08-24T17:41:46.079+0100] {taskinstance.py:2076} INFO - Dependencies all met for dep_context=requeueable deps ti=<TaskInstance: churn_pipeline_taskflow.ingestion scheduled__2025-08-22T23:00:00+00:00 [queued]>
[2025-08-24T17:41:46.079+0100] {taskinstance.py:2306} INFO - Starting attempt 1 of 2
[2025-08-24T17:41:46.083+0100] {taskinstance.py:2330} INFO - Executing <Task(_PythonDecoratedOperator): ingestion> on 2025-08-22 23:00:00+00:00
[2025-08-24T17:41:46.085+0100] {standard_task_runner.py:64} INFO - Started process 25701 to run task
[2025-08-24T17:41:46.088+0100] {standard_task_runner.py:90} INFO - Running: ['airflow', 'tasks', 'run', 'churn_pipeline_taskflow', 'ingestion', 'scheduled__2025-08-22T23:00:00+00:00', '--job-id', '3', '--raw', '--subdir', 'DAGS_FOLDER/airflow_dag.py', '--cfg-path', '/var/folders/c_/hn2ql5p54ylf2dsc72vqg5h40000gn/T/tmp35hw0ny7']
[2025-08-24T17:41:46.090+0100] {standard_task_runner.py:91} INFO - Job 3: Subtask ingestion
[2025-08-24T17:41:46.107+0100] {task_command.py:426} INFO - Running <TaskInstance: churn_pipeline_taskflow.ingestion scheduled__2025-08-22T23:00:00+00:00 [running]> on host mac.communityfibre.co.uk
[2025-08-24T17:41:46.128+0100] {taskinstance.py:2648} INFO - Exporting env vars: AIRFLOW_CTX_DAG_OWNER='shivam' AIRFLOW_CTX_DAG_ID='churn_pipeline_taskflow' AIRFLOW_CTX_TASK_ID='ingestion' AIRFLOW_CTX_EXECUTION_DATE='2025-08-22T23:00:00+00:00' AIRFLOW_CTX_TRY_NUMBER='1' AIRFLOW_CTX_DAG_RUN_ID='scheduled__2025-08-22T23:00:00+00:00'
[2025-08-24T17:41:46.128+0100] {taskinstance.py:430} INFO - ::endgroup::
[2025-08-24T17:41:46.142+0100] {taskinstance.py:441} INFO - ::group::Post task execution logs
[2025-08-24T17:41:46.142+0100] {taskinstance.py:2905} ERROR - Task failed with exception
Traceback (most recent call last):
  File "/Users/homeaccount/miniconda3/envs/churn_pipeline/lib/python3.10/site-packages/airflow/models/taskinstance.py", line 465, in _execute_task
    result = _execute_callable(context=context, **execute_callable_kwargs)
  File "/Users/homeaccount/miniconda3/envs/churn_pipeline/lib/python3.10/site-packages/airflow/models/taskinstance.py", line 432, in _execute_callable
    return execute_callable(context=context, **execute_callable_kwargs)
  File "/Users/homeaccount/miniconda3/envs/churn_pipeline/lib/python3.10/site-packages/airflow/models/baseoperator.py", line 401, in wrapper
    return func(self, *args, **kwargs)
  File "/Users/homeaccount/miniconda3/envs/churn_pipeline/lib/python3.10/site-packages/airflow/decorators/base.py", line 265, in execute
    return_value = super().execute(context)
  File "/Users/homeaccount/miniconda3/envs/churn_pipeline/lib/python3.10/site-packages/airflow/models/baseoperator.py", line 401, in wrapper
    return func(self, *args, **kwargs)
  File "/Users/homeaccount/miniconda3/envs/churn_pipeline/lib/python3.10/site-packages/airflow/operators/python.py", line 235, in execute
    return_value = self.execute_callable()
  File "/Users/homeaccount/miniconda3/envs/churn_pipeline/lib/python3.10/site-packages/airflow/operators/python.py", line 252, in execute_callable
    return self.python_callable(*self.op_args, **self.op_kwargs)
  File "/Users/homeaccount/PycharmProjects/dmml/churn_prediction_pipeline/airflow_home/dags/airflow_dag.py", line 26, in ingestion
    run_cmd(["python", "scripts/ingest.py"])
  File "/Users/homeaccount/PycharmProjects/dmml/churn_prediction_pipeline/airflow_home/dags/airflow_dag.py", line 13, in run_cmd
    subprocess.run(cmd, check=True)
  File "/Users/homeaccount/miniconda3/envs/churn_pipeline/lib/python3.10/subprocess.py", line 526, in run
    raise CalledProcessError(retcode, process.args,
subprocess.CalledProcessError: Command '['python', 'scripts/ingest.py']' returned non-zero exit status 2.
[2025-08-24T17:41:46.147+0100] {taskinstance.py:1206} INFO - Marking task as UP_FOR_RETRY. dag_id=churn_pipeline_taskflow, task_id=ingestion, run_id=scheduled__2025-08-22T23:00:00+00:00, execution_date=20250822T230000, start_date=20250824T164146, end_date=20250824T164146
[2025-08-24T17:41:46.150+0100] {standard_task_runner.py:110} ERROR - Failed to execute job 3 for task ingestion (Command '['python', 'scripts/ingest.py']' returned non-zero exit status 2.; 25701)
[2025-08-24T17:41:46.152+0100] {local_task_job_runner.py:243} INFO - Task exited with return code 1
[2025-08-24T17:41:46.159+0100] {taskinstance.py:3503} INFO - 0 downstream tasks scheduled from follow-on schedule check
[2025-08-24T17:41:46.159+0100] {local_task_job_runner.py:222} INFO - ::endgroup::
[2025-08-24T17:43:59.255+0100] {local_task_job_runner.py:120} INFO - ::group::Pre task execution logs
[2025-08-24T17:43:59.264+0100] {taskinstance.py:2076} INFO - Dependencies all met for dep_context=non-requeueable deps ti=<TaskInstance: churn_pipeline_taskflow.ingestion scheduled__2025-08-22T23:00:00+00:00 [queued]>
[2025-08-24T17:43:59.266+0100] {taskinstance.py:2076} INFO - Dependencies all met for dep_context=requeueable deps ti=<TaskInstance: churn_pipeline_taskflow.ingestion scheduled__2025-08-22T23:00:00+00:00 [queued]>
[2025-08-24T17:43:59.266+0100] {taskinstance.py:2306} INFO - Starting attempt 1 of 6
[2025-08-24T17:43:59.270+0100] {taskinstance.py:2330} INFO - Executing <Task(_PythonDecoratedOperator): ingestion> on 2025-08-22 23:00:00+00:00
[2025-08-24T17:43:59.272+0100] {standard_task_runner.py:64} INFO - Started process 25726 to run task
[2025-08-24T17:43:59.275+0100] {standard_task_runner.py:90} INFO - Running: ['airflow', 'tasks', 'run', 'churn_pipeline_taskflow', 'ingestion', 'scheduled__2025-08-22T23:00:00+00:00', '--job-id', '3', '--raw', '--subdir', 'DAGS_FOLDER/airflow_dag.py', '--cfg-path', '/var/folders/c_/hn2ql5p54ylf2dsc72vqg5h40000gn/T/tmpw7vvbi8h']
[2025-08-24T17:43:59.277+0100] {standard_task_runner.py:91} INFO - Job 3: Subtask ingestion
[2025-08-24T17:43:59.293+0100] {task_command.py:426} INFO - Running <TaskInstance: churn_pipeline_taskflow.ingestion scheduled__2025-08-22T23:00:00+00:00 [running]> on host mac.communityfibre.co.uk
[2025-08-24T17:43:59.313+0100] {taskinstance.py:2648} INFO - Exporting env vars: AIRFLOW_CTX_DAG_OWNER='shivam' AIRFLOW_CTX_DAG_ID='churn_pipeline_taskflow' AIRFLOW_CTX_TASK_ID='ingestion' AIRFLOW_CTX_EXECUTION_DATE='2025-08-22T23:00:00+00:00' AIRFLOW_CTX_TRY_NUMBER='1' AIRFLOW_CTX_DAG_RUN_ID='scheduled__2025-08-22T23:00:00+00:00'
[2025-08-24T17:43:59.313+0100] {taskinstance.py:430} INFO - ::endgroup::
[2025-08-24T17:43:59.328+0100] {taskinstance.py:441} INFO - ::group::Post task execution logs
[2025-08-24T17:43:59.329+0100] {taskinstance.py:2905} ERROR - Task failed with exception
Traceback (most recent call last):
  File "/Users/homeaccount/miniconda3/envs/churn_pipeline/lib/python3.10/site-packages/airflow/models/taskinstance.py", line 465, in _execute_task
    result = _execute_callable(context=context, **execute_callable_kwargs)
  File "/Users/homeaccount/miniconda3/envs/churn_pipeline/lib/python3.10/site-packages/airflow/models/taskinstance.py", line 432, in _execute_callable
    return execute_callable(context=context, **execute_callable_kwargs)
  File "/Users/homeaccount/miniconda3/envs/churn_pipeline/lib/python3.10/site-packages/airflow/models/baseoperator.py", line 401, in wrapper
    return func(self, *args, **kwargs)
  File "/Users/homeaccount/miniconda3/envs/churn_pipeline/lib/python3.10/site-packages/airflow/decorators/base.py", line 265, in execute
    return_value = super().execute(context)
  File "/Users/homeaccount/miniconda3/envs/churn_pipeline/lib/python3.10/site-packages/airflow/models/baseoperator.py", line 401, in wrapper
    return func(self, *args, **kwargs)
  File "/Users/homeaccount/miniconda3/envs/churn_pipeline/lib/python3.10/site-packages/airflow/operators/python.py", line 235, in execute
    return_value = self.execute_callable()
  File "/Users/homeaccount/miniconda3/envs/churn_pipeline/lib/python3.10/site-packages/airflow/operators/python.py", line 252, in execute_callable
    return self.python_callable(*self.op_args, **self.op_kwargs)
  File "/Users/homeaccount/PycharmProjects/dmml/churn_prediction_pipeline/airflow_home/dags/airflow_dag.py", line 26, in ingestion
    run_cmd(["python", "scripts/ingest.py"])
  File "/Users/homeaccount/PycharmProjects/dmml/churn_prediction_pipeline/airflow_home/dags/airflow_dag.py", line 13, in run_cmd
    subprocess.run(cmd, check=True)
  File "/Users/homeaccount/miniconda3/envs/churn_pipeline/lib/python3.10/subprocess.py", line 526, in run
    raise CalledProcessError(retcode, process.args,
subprocess.CalledProcessError: Command '['python', 'scripts/ingest.py']' returned non-zero exit status 2.
[2025-08-24T17:43:59.333+0100] {taskinstance.py:1206} INFO - Marking task as UP_FOR_RETRY. dag_id=churn_pipeline_taskflow, task_id=ingestion, run_id=scheduled__2025-08-22T23:00:00+00:00, execution_date=20250822T230000, start_date=20250824T164359, end_date=20250824T164359
[2025-08-24T17:43:59.336+0100] {standard_task_runner.py:110} ERROR - Failed to execute job 3 for task ingestion (Command '['python', 'scripts/ingest.py']' returned non-zero exit status 2.; 25726)
[2025-08-24T17:43:59.382+0100] {local_task_job_runner.py:243} INFO - Task exited with return code 1
[2025-08-24T17:43:59.390+0100] {taskinstance.py:3503} INFO - 0 downstream tasks scheduled from follow-on schedule check
[2025-08-24T17:43:59.390+0100] {local_task_job_runner.py:222} INFO - ::endgroup::
[2025-08-24T18:10:07.369+0100] {local_task_job_runner.py:120} INFO - ::group::Pre task execution logs
[2025-08-24T18:10:07.378+0100] {taskinstance.py:2076} INFO - Dependencies all met for dep_context=non-requeueable deps ti=<TaskInstance: churn_pipeline_taskflow.ingestion scheduled__2025-08-22T23:00:00+00:00 [queued]>
[2025-08-24T18:10:07.380+0100] {taskinstance.py:2076} INFO - Dependencies all met for dep_context=requeueable deps ti=<TaskInstance: churn_pipeline_taskflow.ingestion scheduled__2025-08-22T23:00:00+00:00 [queued]>
[2025-08-24T18:10:07.380+0100] {taskinstance.py:2306} INFO - Starting attempt 1 of 6
[2025-08-24T18:10:07.384+0100] {taskinstance.py:2330} INFO - Executing <Task(_PythonDecoratedOperator): ingestion> on 2025-08-22 23:00:00+00:00
[2025-08-24T18:10:07.386+0100] {standard_task_runner.py:64} INFO - Started process 26209 to run task
[2025-08-24T18:10:07.389+0100] {standard_task_runner.py:90} INFO - Running: ['airflow', 'tasks', 'run', 'churn_pipeline_taskflow', 'ingestion', 'scheduled__2025-08-22T23:00:00+00:00', '--job-id', '17', '--raw', '--subdir', 'DAGS_FOLDER/.ipynb_checkpoints/airflow_dag-checkpoint.py', '--cfg-path', '/var/folders/c_/hn2ql5p54ylf2dsc72vqg5h40000gn/T/tmpcvrck45f']
[2025-08-24T18:10:07.391+0100] {standard_task_runner.py:91} INFO - Job 17: Subtask ingestion
[2025-08-24T18:10:07.407+0100] {task_command.py:426} INFO - Running <TaskInstance: churn_pipeline_taskflow.ingestion scheduled__2025-08-22T23:00:00+00:00 [running]> on host mac.communityfibre.co.uk
[2025-08-24T18:10:07.428+0100] {taskinstance.py:2648} INFO - Exporting env vars: AIRFLOW_CTX_DAG_OWNER='shivam' AIRFLOW_CTX_DAG_ID='churn_pipeline_taskflow' AIRFLOW_CTX_TASK_ID='ingestion' AIRFLOW_CTX_EXECUTION_DATE='2025-08-22T23:00:00+00:00' AIRFLOW_CTX_TRY_NUMBER='1' AIRFLOW_CTX_DAG_RUN_ID='scheduled__2025-08-22T23:00:00+00:00'
[2025-08-24T18:10:07.428+0100] {taskinstance.py:430} INFO - ::endgroup::
[2025-08-24T18:10:11.414+0100] {taskinstance.py:441} INFO - ::group::Post task execution logs
[2025-08-24T18:10:11.415+0100] {taskinstance.py:2905} ERROR - Task failed with exception
Traceback (most recent call last):
  File "/Users/homeaccount/miniconda3/envs/churn_pipeline/lib/python3.10/site-packages/airflow/models/taskinstance.py", line 465, in _execute_task
    result = _execute_callable(context=context, **execute_callable_kwargs)
  File "/Users/homeaccount/miniconda3/envs/churn_pipeline/lib/python3.10/site-packages/airflow/models/taskinstance.py", line 432, in _execute_callable
    return execute_callable(context=context, **execute_callable_kwargs)
  File "/Users/homeaccount/miniconda3/envs/churn_pipeline/lib/python3.10/site-packages/airflow/models/baseoperator.py", line 401, in wrapper
    return func(self, *args, **kwargs)
  File "/Users/homeaccount/miniconda3/envs/churn_pipeline/lib/python3.10/site-packages/airflow/decorators/base.py", line 265, in execute
    return_value = super().execute(context)
  File "/Users/homeaccount/miniconda3/envs/churn_pipeline/lib/python3.10/site-packages/airflow/models/baseoperator.py", line 401, in wrapper
    return func(self, *args, **kwargs)
  File "/Users/homeaccount/miniconda3/envs/churn_pipeline/lib/python3.10/site-packages/airflow/operators/python.py", line 235, in execute
    return_value = self.execute_callable()
  File "/Users/homeaccount/miniconda3/envs/churn_pipeline/lib/python3.10/site-packages/airflow/operators/python.py", line 252, in execute_callable
    return self.python_callable(*self.op_args, **self.op_kwargs)
  File "/Users/homeaccount/PycharmProjects/dmml/churn_prediction_pipeline/airflow_home/dags/.ipynb_checkpoints/airflow_dag-checkpoint.py", line 30, in ingestion
    run_cmd(["dvc", "add", "data/raw/telco_churn.csv", "data/raw/hf_bank_customer_support.csv"])
  File "/Users/homeaccount/PycharmProjects/dmml/churn_prediction_pipeline/airflow_home/dags/.ipynb_checkpoints/airflow_dag-checkpoint.py", line 16, in run_cmd
    subprocess.run(cmd, check=True)
  File "/Users/homeaccount/miniconda3/envs/churn_pipeline/lib/python3.10/subprocess.py", line 526, in run
    raise CalledProcessError(retcode, process.args,
subprocess.CalledProcessError: Command '['dvc', 'add', 'data/raw/telco_churn.csv', 'data/raw/hf_bank_customer_support.csv']' returned non-zero exit status 1.
[2025-08-24T18:10:11.422+0100] {taskinstance.py:1206} INFO - Marking task as UP_FOR_RETRY. dag_id=churn_pipeline_taskflow, task_id=ingestion, run_id=scheduled__2025-08-22T23:00:00+00:00, execution_date=20250822T230000, start_date=20250824T171007, end_date=20250824T171011
[2025-08-24T18:10:11.425+0100] {standard_task_runner.py:110} ERROR - Failed to execute job 17 for task ingestion (Command '['dvc', 'add', 'data/raw/telco_churn.csv', 'data/raw/hf_bank_customer_support.csv']' returned non-zero exit status 1.; 26209)
[2025-08-24T18:10:11.435+0100] {local_task_job_runner.py:243} INFO - Task exited with return code 1
[2025-08-24T18:10:11.442+0100] {taskinstance.py:3503} INFO - 0 downstream tasks scheduled from follow-on schedule check
[2025-08-24T18:10:11.442+0100] {local_task_job_runner.py:222} INFO - ::endgroup::
[2025-08-24T18:13:37.597+0100] {local_task_job_runner.py:120} INFO - ::group::Pre task execution logs
[2025-08-24T18:13:37.605+0100] {taskinstance.py:2076} INFO - Dependencies all met for dep_context=non-requeueable deps ti=<TaskInstance: churn_pipeline_taskflow.ingestion scheduled__2025-08-22T23:00:00+00:00 [queued]>
[2025-08-24T18:13:37.607+0100] {taskinstance.py:2076} INFO - Dependencies all met for dep_context=requeueable deps ti=<TaskInstance: churn_pipeline_taskflow.ingestion scheduled__2025-08-22T23:00:00+00:00 [queued]>
[2025-08-24T18:13:37.607+0100] {taskinstance.py:2306} INFO - Starting attempt 1 of 6
[2025-08-24T18:13:37.611+0100] {taskinstance.py:2330} INFO - Executing <Task(_PythonDecoratedOperator): ingestion> on 2025-08-22 23:00:00+00:00
[2025-08-24T18:13:37.613+0100] {standard_task_runner.py:64} INFO - Started process 26323 to run task
[2025-08-24T18:13:37.615+0100] {standard_task_runner.py:90} INFO - Running: ['airflow', 'tasks', 'run', 'churn_pipeline_taskflow', 'ingestion', 'scheduled__2025-08-22T23:00:00+00:00', '--job-id', '17', '--raw', '--subdir', 'DAGS_FOLDER/.ipynb_checkpoints/airflow_dag-checkpoint.py', '--cfg-path', '/var/folders/c_/hn2ql5p54ylf2dsc72vqg5h40000gn/T/tmptcqyko53']
[2025-08-24T18:13:37.617+0100] {standard_task_runner.py:91} INFO - Job 17: Subtask ingestion
[2025-08-24T18:13:37.631+0100] {task_command.py:426} INFO - Running <TaskInstance: churn_pipeline_taskflow.ingestion scheduled__2025-08-22T23:00:00+00:00 [running]> on host mac.communityfibre.co.uk
[2025-08-24T18:13:37.651+0100] {taskinstance.py:2648} INFO - Exporting env vars: AIRFLOW_CTX_DAG_OWNER='shivam' AIRFLOW_CTX_DAG_ID='churn_pipeline_taskflow' AIRFLOW_CTX_TASK_ID='ingestion' AIRFLOW_CTX_EXECUTION_DATE='2025-08-22T23:00:00+00:00' AIRFLOW_CTX_TRY_NUMBER='1' AIRFLOW_CTX_DAG_RUN_ID='scheduled__2025-08-22T23:00:00+00:00'
[2025-08-24T18:13:37.651+0100] {taskinstance.py:430} INFO - ::endgroup::
[2025-08-24T18:13:37.652+0100] {logging_mixin.py:188} INFO - /Users/homeaccount/PycharmProjects/dmml/churn_prediction_pipeline
[2025-08-24T18:13:41.305+0100] {taskinstance.py:441} INFO - ::group::Post task execution logs
[2025-08-24T18:13:41.306+0100] {taskinstance.py:2905} ERROR - Task failed with exception
Traceback (most recent call last):
  File "/Users/homeaccount/miniconda3/envs/churn_pipeline/lib/python3.10/site-packages/airflow/models/taskinstance.py", line 465, in _execute_task
    result = _execute_callable(context=context, **execute_callable_kwargs)
  File "/Users/homeaccount/miniconda3/envs/churn_pipeline/lib/python3.10/site-packages/airflow/models/taskinstance.py", line 432, in _execute_callable
    return execute_callable(context=context, **execute_callable_kwargs)
  File "/Users/homeaccount/miniconda3/envs/churn_pipeline/lib/python3.10/site-packages/airflow/models/baseoperator.py", line 401, in wrapper
    return func(self, *args, **kwargs)
  File "/Users/homeaccount/miniconda3/envs/churn_pipeline/lib/python3.10/site-packages/airflow/decorators/base.py", line 265, in execute
    return_value = super().execute(context)
  File "/Users/homeaccount/miniconda3/envs/churn_pipeline/lib/python3.10/site-packages/airflow/models/baseoperator.py", line 401, in wrapper
    return func(self, *args, **kwargs)
  File "/Users/homeaccount/miniconda3/envs/churn_pipeline/lib/python3.10/site-packages/airflow/operators/python.py", line 235, in execute
    return_value = self.execute_callable()
  File "/Users/homeaccount/miniconda3/envs/churn_pipeline/lib/python3.10/site-packages/airflow/operators/python.py", line 252, in execute_callable
    return self.python_callable(*self.op_args, **self.op_kwargs)
  File "/Users/homeaccount/PycharmProjects/dmml/churn_prediction_pipeline/airflow_home/dags/.ipynb_checkpoints/airflow_dag-checkpoint.py", line 31, in ingestion
    run_cmd(["dvc", "add", "data/raw/telco_churn.csv", "data/raw/hf_bank_customer_support.csv"])
  File "/Users/homeaccount/PycharmProjects/dmml/churn_prediction_pipeline/airflow_home/dags/.ipynb_checkpoints/airflow_dag-checkpoint.py", line 16, in run_cmd
    subprocess.run(cmd, check=True)
  File "/Users/homeaccount/miniconda3/envs/churn_pipeline/lib/python3.10/subprocess.py", line 526, in run
    raise CalledProcessError(retcode, process.args,
subprocess.CalledProcessError: Command '['dvc', 'add', 'data/raw/telco_churn.csv', 'data/raw/hf_bank_customer_support.csv']' returned non-zero exit status 1.
[2025-08-24T18:13:41.312+0100] {taskinstance.py:1206} INFO - Marking task as UP_FOR_RETRY. dag_id=churn_pipeline_taskflow, task_id=ingestion, run_id=scheduled__2025-08-22T23:00:00+00:00, execution_date=20250822T230000, start_date=20250824T171337, end_date=20250824T171341
[2025-08-24T18:13:41.316+0100] {standard_task_runner.py:110} ERROR - Failed to execute job 17 for task ingestion (Command '['dvc', 'add', 'data/raw/telco_churn.csv', 'data/raw/hf_bank_customer_support.csv']' returned non-zero exit status 1.; 26323)
[2025-08-24T18:13:41.326+0100] {local_task_job_runner.py:243} INFO - Task exited with return code 1
[2025-08-24T18:13:41.334+0100] {taskinstance.py:3503} INFO - 0 downstream tasks scheduled from follow-on schedule check
[2025-08-24T18:13:41.334+0100] {local_task_job_runner.py:222} INFO - ::endgroup::
