[2025-08-24T17:42:51.224+0100] {local_task_job_runner.py:120} INFO - ::group::Pre task execution logs
[2025-08-24T17:42:51.230+0100] {taskinstance.py:2076} INFO - Dependencies all met for dep_context=non-requeueable deps ti=<TaskInstance: churn_pipeline_taskflow.ingestion scheduled__2025-08-22T23:00:00+00:00 [queued]>
[2025-08-24T17:42:51.232+0100] {taskinstance.py:2076} INFO - Dependencies all met for dep_context=requeueable deps ti=<TaskInstance: churn_pipeline_taskflow.ingestion scheduled__2025-08-22T23:00:00+00:00 [queued]>
[2025-08-24T17:42:51.232+0100] {taskinstance.py:2306} INFO - Starting attempt 2 of 2
[2025-08-24T17:42:51.236+0100] {taskinstance.py:2330} INFO - Executing <Task(_PythonDecoratedOperator): ingestion> on 2025-08-22 23:00:00+00:00
[2025-08-24T17:42:51.238+0100] {standard_task_runner.py:64} INFO - Started process 25713 to run task
[2025-08-24T17:42:51.240+0100] {standard_task_runner.py:90} INFO - Running: ['airflow', 'tasks', 'run', 'churn_pipeline_taskflow', 'ingestion', 'scheduled__2025-08-22T23:00:00+00:00', '--job-id', '5', '--raw', '--subdir', 'DAGS_FOLDER/airflow_dag.py', '--cfg-path', '/var/folders/c_/hn2ql5p54ylf2dsc72vqg5h40000gn/T/tmp0crad_qk']
[2025-08-24T17:42:51.241+0100] {standard_task_runner.py:91} INFO - Job 5: Subtask ingestion
[2025-08-24T17:42:51.255+0100] {task_command.py:426} INFO - Running <TaskInstance: churn_pipeline_taskflow.ingestion scheduled__2025-08-22T23:00:00+00:00 [running]> on host mac.communityfibre.co.uk
[2025-08-24T17:42:51.274+0100] {taskinstance.py:2648} INFO - Exporting env vars: AIRFLOW_CTX_DAG_OWNER='shivam' AIRFLOW_CTX_DAG_ID='churn_pipeline_taskflow' AIRFLOW_CTX_TASK_ID='ingestion' AIRFLOW_CTX_EXECUTION_DATE='2025-08-22T23:00:00+00:00' AIRFLOW_CTX_TRY_NUMBER='2' AIRFLOW_CTX_DAG_RUN_ID='scheduled__2025-08-22T23:00:00+00:00'
[2025-08-24T17:42:51.274+0100] {taskinstance.py:430} INFO - ::endgroup::
[2025-08-24T17:42:51.287+0100] {taskinstance.py:441} INFO - ::group::Post task execution logs
[2025-08-24T17:42:51.288+0100] {taskinstance.py:2905} ERROR - Task failed with exception
Traceback (most recent call last):
  File "/Users/homeaccount/miniconda3/envs/churn_pipeline/lib/python3.10/site-packages/airflow/models/taskinstance.py", line 465, in _execute_task
    result = _execute_callable(context=context, **execute_callable_kwargs)
  File "/Users/homeaccount/miniconda3/envs/churn_pipeline/lib/python3.10/site-packages/airflow/models/taskinstance.py", line 432, in _execute_callable
    return execute_callable(context=context, **execute_callable_kwargs)
  File "/Users/homeaccount/miniconda3/envs/churn_pipeline/lib/python3.10/site-packages/airflow/models/baseoperator.py", line 401, in wrapper
    return func(self, *args, **kwargs)
  File "/Users/homeaccount/miniconda3/envs/churn_pipeline/lib/python3.10/site-packages/airflow/decorators/base.py", line 265, in execute
    return_value = super().execute(context)
  File "/Users/homeaccount/miniconda3/envs/churn_pipeline/lib/python3.10/site-packages/airflow/models/baseoperator.py", line 401, in wrapper
    return func(self, *args, **kwargs)
  File "/Users/homeaccount/miniconda3/envs/churn_pipeline/lib/python3.10/site-packages/airflow/operators/python.py", line 235, in execute
    return_value = self.execute_callable()
  File "/Users/homeaccount/miniconda3/envs/churn_pipeline/lib/python3.10/site-packages/airflow/operators/python.py", line 252, in execute_callable
    return self.python_callable(*self.op_args, **self.op_kwargs)
  File "/Users/homeaccount/PycharmProjects/dmml/churn_prediction_pipeline/airflow_home/dags/airflow_dag.py", line 26, in ingestion
    run_cmd(["python", "scripts/ingest.py"])
  File "/Users/homeaccount/PycharmProjects/dmml/churn_prediction_pipeline/airflow_home/dags/airflow_dag.py", line 13, in run_cmd
    subprocess.run(cmd, check=True)
  File "/Users/homeaccount/miniconda3/envs/churn_pipeline/lib/python3.10/subprocess.py", line 526, in run
    raise CalledProcessError(retcode, process.args,
subprocess.CalledProcessError: Command '['python', 'scripts/ingest.py']' returned non-zero exit status 2.
[2025-08-24T17:42:51.293+0100] {taskinstance.py:1206} INFO - Marking task as FAILED. dag_id=churn_pipeline_taskflow, task_id=ingestion, run_id=scheduled__2025-08-22T23:00:00+00:00, execution_date=20250822T230000, start_date=20250824T164251, end_date=20250824T164251
[2025-08-24T17:42:51.296+0100] {standard_task_runner.py:110} ERROR - Failed to execute job 5 for task ingestion (Command '['python', 'scripts/ingest.py']' returned non-zero exit status 2.; 25713)
[2025-08-24T17:42:51.302+0100] {local_task_job_runner.py:243} INFO - Task exited with return code 1
[2025-08-24T17:42:51.309+0100] {taskinstance.py:3503} INFO - 0 downstream tasks scheduled from follow-on schedule check
[2025-08-24T17:42:51.310+0100] {local_task_job_runner.py:222} INFO - ::endgroup::
[2025-08-24T17:44:05.185+0100] {local_task_job_runner.py:120} INFO - ::group::Pre task execution logs
[2025-08-24T17:44:05.193+0100] {taskinstance.py:2076} INFO - Dependencies all met for dep_context=non-requeueable deps ti=<TaskInstance: churn_pipeline_taskflow.ingestion scheduled__2025-08-22T23:00:00+00:00 [queued]>
[2025-08-24T17:44:05.194+0100] {taskinstance.py:2076} INFO - Dependencies all met for dep_context=requeueable deps ti=<TaskInstance: churn_pipeline_taskflow.ingestion scheduled__2025-08-22T23:00:00+00:00 [queued]>
[2025-08-24T17:44:05.195+0100] {taskinstance.py:2306} INFO - Starting attempt 2 of 6
[2025-08-24T17:44:05.198+0100] {taskinstance.py:2330} INFO - Executing <Task(_PythonDecoratedOperator): ingestion> on 2025-08-22 23:00:00+00:00
[2025-08-24T17:44:05.200+0100] {standard_task_runner.py:64} INFO - Started process 25733 to run task
[2025-08-24T17:44:05.203+0100] {standard_task_runner.py:90} INFO - Running: ['airflow', 'tasks', 'run', 'churn_pipeline_taskflow', 'ingestion', 'scheduled__2025-08-22T23:00:00+00:00', '--job-id', '5', '--raw', '--subdir', 'DAGS_FOLDER/airflow_dag.py', '--cfg-path', '/var/folders/c_/hn2ql5p54ylf2dsc72vqg5h40000gn/T/tmpqd1n755l']
[2025-08-24T17:44:05.204+0100] {standard_task_runner.py:91} INFO - Job 5: Subtask ingestion
[2025-08-24T17:44:05.221+0100] {task_command.py:426} INFO - Running <TaskInstance: churn_pipeline_taskflow.ingestion scheduled__2025-08-22T23:00:00+00:00 [running]> on host mac.communityfibre.co.uk
[2025-08-24T17:44:05.243+0100] {taskinstance.py:2648} INFO - Exporting env vars: AIRFLOW_CTX_DAG_OWNER='shivam' AIRFLOW_CTX_DAG_ID='churn_pipeline_taskflow' AIRFLOW_CTX_TASK_ID='ingestion' AIRFLOW_CTX_EXECUTION_DATE='2025-08-22T23:00:00+00:00' AIRFLOW_CTX_TRY_NUMBER='2' AIRFLOW_CTX_DAG_RUN_ID='scheduled__2025-08-22T23:00:00+00:00'
[2025-08-24T17:44:05.244+0100] {taskinstance.py:430} INFO - ::endgroup::
[2025-08-24T17:44:05.259+0100] {taskinstance.py:441} INFO - ::group::Post task execution logs
[2025-08-24T17:44:05.259+0100] {taskinstance.py:2905} ERROR - Task failed with exception
Traceback (most recent call last):
  File "/Users/homeaccount/miniconda3/envs/churn_pipeline/lib/python3.10/site-packages/airflow/models/taskinstance.py", line 465, in _execute_task
    result = _execute_callable(context=context, **execute_callable_kwargs)
  File "/Users/homeaccount/miniconda3/envs/churn_pipeline/lib/python3.10/site-packages/airflow/models/taskinstance.py", line 432, in _execute_callable
    return execute_callable(context=context, **execute_callable_kwargs)
  File "/Users/homeaccount/miniconda3/envs/churn_pipeline/lib/python3.10/site-packages/airflow/models/baseoperator.py", line 401, in wrapper
    return func(self, *args, **kwargs)
  File "/Users/homeaccount/miniconda3/envs/churn_pipeline/lib/python3.10/site-packages/airflow/decorators/base.py", line 265, in execute
    return_value = super().execute(context)
  File "/Users/homeaccount/miniconda3/envs/churn_pipeline/lib/python3.10/site-packages/airflow/models/baseoperator.py", line 401, in wrapper
    return func(self, *args, **kwargs)
  File "/Users/homeaccount/miniconda3/envs/churn_pipeline/lib/python3.10/site-packages/airflow/operators/python.py", line 235, in execute
    return_value = self.execute_callable()
  File "/Users/homeaccount/miniconda3/envs/churn_pipeline/lib/python3.10/site-packages/airflow/operators/python.py", line 252, in execute_callable
    return self.python_callable(*self.op_args, **self.op_kwargs)
  File "/Users/homeaccount/PycharmProjects/dmml/churn_prediction_pipeline/airflow_home/dags/airflow_dag.py", line 26, in ingestion
    run_cmd(["python", "scripts/ingest.py"])
  File "/Users/homeaccount/PycharmProjects/dmml/churn_prediction_pipeline/airflow_home/dags/airflow_dag.py", line 13, in run_cmd
    subprocess.run(cmd, check=True)
  File "/Users/homeaccount/miniconda3/envs/churn_pipeline/lib/python3.10/subprocess.py", line 526, in run
    raise CalledProcessError(retcode, process.args,
subprocess.CalledProcessError: Command '['python', 'scripts/ingest.py']' returned non-zero exit status 2.
[2025-08-24T17:44:05.262+0100] {taskinstance.py:1206} INFO - Marking task as UP_FOR_RETRY. dag_id=churn_pipeline_taskflow, task_id=ingestion, run_id=scheduled__2025-08-22T23:00:00+00:00, execution_date=20250822T230000, start_date=20250824T164405, end_date=20250824T164405
[2025-08-24T17:44:05.265+0100] {standard_task_runner.py:110} ERROR - Failed to execute job 5 for task ingestion (Command '['python', 'scripts/ingest.py']' returned non-zero exit status 2.; 25733)
[2025-08-24T17:44:05.309+0100] {local_task_job_runner.py:243} INFO - Task exited with return code 1
[2025-08-24T17:44:05.317+0100] {taskinstance.py:3503} INFO - 0 downstream tasks scheduled from follow-on schedule check
[2025-08-24T17:44:05.318+0100] {local_task_job_runner.py:222} INFO - ::endgroup::
[2025-08-24T18:10:18.677+0100] {local_task_job_runner.py:120} INFO - ::group::Pre task execution logs
[2025-08-24T18:10:18.685+0100] {taskinstance.py:2076} INFO - Dependencies all met for dep_context=non-requeueable deps ti=<TaskInstance: churn_pipeline_taskflow.ingestion scheduled__2025-08-22T23:00:00+00:00 [queued]>
[2025-08-24T18:10:18.687+0100] {taskinstance.py:2076} INFO - Dependencies all met for dep_context=requeueable deps ti=<TaskInstance: churn_pipeline_taskflow.ingestion scheduled__2025-08-22T23:00:00+00:00 [queued]>
[2025-08-24T18:10:18.687+0100] {taskinstance.py:2306} INFO - Starting attempt 2 of 6
[2025-08-24T18:10:18.691+0100] {taskinstance.py:2330} INFO - Executing <Task(_PythonDecoratedOperator): ingestion> on 2025-08-22 23:00:00+00:00
[2025-08-24T18:10:18.693+0100] {standard_task_runner.py:64} INFO - Started process 26221 to run task
[2025-08-24T18:10:18.695+0100] {standard_task_runner.py:90} INFO - Running: ['airflow', 'tasks', 'run', 'churn_pipeline_taskflow', 'ingestion', 'scheduled__2025-08-22T23:00:00+00:00', '--job-id', '19', '--raw', '--subdir', 'DAGS_FOLDER/airflow_dag.py', '--cfg-path', '/var/folders/c_/hn2ql5p54ylf2dsc72vqg5h40000gn/T/tmpuby4521a']
[2025-08-24T18:10:18.697+0100] {standard_task_runner.py:91} INFO - Job 19: Subtask ingestion
[2025-08-24T18:10:18.710+0100] {task_command.py:426} INFO - Running <TaskInstance: churn_pipeline_taskflow.ingestion scheduled__2025-08-22T23:00:00+00:00 [running]> on host mac.communityfibre.co.uk
[2025-08-24T18:10:18.730+0100] {taskinstance.py:2648} INFO - Exporting env vars: AIRFLOW_CTX_DAG_OWNER='shivam' AIRFLOW_CTX_DAG_ID='churn_pipeline_taskflow' AIRFLOW_CTX_TASK_ID='ingestion' AIRFLOW_CTX_EXECUTION_DATE='2025-08-22T23:00:00+00:00' AIRFLOW_CTX_TRY_NUMBER='2' AIRFLOW_CTX_DAG_RUN_ID='scheduled__2025-08-22T23:00:00+00:00'
[2025-08-24T18:10:18.730+0100] {taskinstance.py:430} INFO - ::endgroup::
[2025-08-24T18:10:21.797+0100] {taskinstance.py:441} INFO - ::group::Post task execution logs
[2025-08-24T18:10:21.798+0100] {taskinstance.py:2905} ERROR - Task failed with exception
Traceback (most recent call last):
  File "/Users/homeaccount/miniconda3/envs/churn_pipeline/lib/python3.10/site-packages/airflow/models/taskinstance.py", line 465, in _execute_task
    result = _execute_callable(context=context, **execute_callable_kwargs)
  File "/Users/homeaccount/miniconda3/envs/churn_pipeline/lib/python3.10/site-packages/airflow/models/taskinstance.py", line 432, in _execute_callable
    return execute_callable(context=context, **execute_callable_kwargs)
  File "/Users/homeaccount/miniconda3/envs/churn_pipeline/lib/python3.10/site-packages/airflow/models/baseoperator.py", line 401, in wrapper
    return func(self, *args, **kwargs)
  File "/Users/homeaccount/miniconda3/envs/churn_pipeline/lib/python3.10/site-packages/airflow/decorators/base.py", line 265, in execute
    return_value = super().execute(context)
  File "/Users/homeaccount/miniconda3/envs/churn_pipeline/lib/python3.10/site-packages/airflow/models/baseoperator.py", line 401, in wrapper
    return func(self, *args, **kwargs)
  File "/Users/homeaccount/miniconda3/envs/churn_pipeline/lib/python3.10/site-packages/airflow/operators/python.py", line 235, in execute
    return_value = self.execute_callable()
  File "/Users/homeaccount/miniconda3/envs/churn_pipeline/lib/python3.10/site-packages/airflow/operators/python.py", line 252, in execute_callable
    return self.python_callable(*self.op_args, **self.op_kwargs)
  File "/Users/homeaccount/PycharmProjects/dmml/churn_prediction_pipeline/airflow_home/dags/airflow_dag.py", line 30, in ingestion
    run_cmd(["dvc", "add", "data/raw/telco_churn.csv", "data/raw/hf_bank_customer_support.csv"])
  File "/Users/homeaccount/PycharmProjects/dmml/churn_prediction_pipeline/airflow_home/dags/airflow_dag.py", line 16, in run_cmd
    subprocess.run(cmd, check=True)
  File "/Users/homeaccount/miniconda3/envs/churn_pipeline/lib/python3.10/subprocess.py", line 526, in run
    raise CalledProcessError(retcode, process.args,
subprocess.CalledProcessError: Command '['dvc', 'add', 'data/raw/telco_churn.csv', 'data/raw/hf_bank_customer_support.csv']' returned non-zero exit status 1.
[2025-08-24T18:10:21.801+0100] {taskinstance.py:1206} INFO - Marking task as UP_FOR_RETRY. dag_id=churn_pipeline_taskflow, task_id=ingestion, run_id=scheduled__2025-08-22T23:00:00+00:00, execution_date=20250822T230000, start_date=20250824T171018, end_date=20250824T171021
[2025-08-24T18:10:21.805+0100] {standard_task_runner.py:110} ERROR - Failed to execute job 19 for task ingestion (Command '['dvc', 'add', 'data/raw/telco_churn.csv', 'data/raw/hf_bank_customer_support.csv']' returned non-zero exit status 1.; 26221)
[2025-08-24T18:10:21.841+0100] {local_task_job_runner.py:243} INFO - Task exited with return code 1
[2025-08-24T18:10:21.850+0100] {taskinstance.py:3503} INFO - 0 downstream tasks scheduled from follow-on schedule check
[2025-08-24T18:10:21.850+0100] {local_task_job_runner.py:222} INFO - ::endgroup::
[2025-08-24T18:13:47.191+0100] {local_task_job_runner.py:120} INFO - ::group::Pre task execution logs
[2025-08-24T18:13:47.199+0100] {taskinstance.py:2076} INFO - Dependencies all met for dep_context=non-requeueable deps ti=<TaskInstance: churn_pipeline_taskflow.ingestion scheduled__2025-08-22T23:00:00+00:00 [queued]>
[2025-08-24T18:13:47.202+0100] {taskinstance.py:2076} INFO - Dependencies all met for dep_context=requeueable deps ti=<TaskInstance: churn_pipeline_taskflow.ingestion scheduled__2025-08-22T23:00:00+00:00 [queued]>
[2025-08-24T18:13:47.202+0100] {taskinstance.py:2306} INFO - Starting attempt 2 of 6
[2025-08-24T18:13:47.206+0100] {taskinstance.py:2330} INFO - Executing <Task(_PythonDecoratedOperator): ingestion> on 2025-08-22 23:00:00+00:00
[2025-08-24T18:13:47.208+0100] {standard_task_runner.py:64} INFO - Started process 26334 to run task
[2025-08-24T18:13:47.210+0100] {standard_task_runner.py:90} INFO - Running: ['airflow', 'tasks', 'run', 'churn_pipeline_taskflow', 'ingestion', 'scheduled__2025-08-22T23:00:00+00:00', '--job-id', '19', '--raw', '--subdir', 'DAGS_FOLDER/.ipynb_checkpoints/airflow_dag-checkpoint.py', '--cfg-path', '/var/folders/c_/hn2ql5p54ylf2dsc72vqg5h40000gn/T/tmpmpwd_pic']
[2025-08-24T18:13:47.211+0100] {standard_task_runner.py:91} INFO - Job 19: Subtask ingestion
[2025-08-24T18:13:47.225+0100] {task_command.py:426} INFO - Running <TaskInstance: churn_pipeline_taskflow.ingestion scheduled__2025-08-22T23:00:00+00:00 [running]> on host mac.communityfibre.co.uk
[2025-08-24T18:13:47.245+0100] {taskinstance.py:2648} INFO - Exporting env vars: AIRFLOW_CTX_DAG_OWNER='shivam' AIRFLOW_CTX_DAG_ID='churn_pipeline_taskflow' AIRFLOW_CTX_TASK_ID='ingestion' AIRFLOW_CTX_EXECUTION_DATE='2025-08-22T23:00:00+00:00' AIRFLOW_CTX_TRY_NUMBER='2' AIRFLOW_CTX_DAG_RUN_ID='scheduled__2025-08-22T23:00:00+00:00'
[2025-08-24T18:13:47.246+0100] {taskinstance.py:430} INFO - ::endgroup::
[2025-08-24T18:13:47.246+0100] {logging_mixin.py:188} INFO - /Users/homeaccount/PycharmProjects/dmml/churn_prediction_pipeline
[2025-08-24T18:13:50.208+0100] {taskinstance.py:441} INFO - ::group::Post task execution logs
[2025-08-24T18:13:50.209+0100] {taskinstance.py:2905} ERROR - Task failed with exception
Traceback (most recent call last):
  File "/Users/homeaccount/miniconda3/envs/churn_pipeline/lib/python3.10/site-packages/airflow/models/taskinstance.py", line 465, in _execute_task
    result = _execute_callable(context=context, **execute_callable_kwargs)
  File "/Users/homeaccount/miniconda3/envs/churn_pipeline/lib/python3.10/site-packages/airflow/models/taskinstance.py", line 432, in _execute_callable
    return execute_callable(context=context, **execute_callable_kwargs)
  File "/Users/homeaccount/miniconda3/envs/churn_pipeline/lib/python3.10/site-packages/airflow/models/baseoperator.py", line 401, in wrapper
    return func(self, *args, **kwargs)
  File "/Users/homeaccount/miniconda3/envs/churn_pipeline/lib/python3.10/site-packages/airflow/decorators/base.py", line 265, in execute
    return_value = super().execute(context)
  File "/Users/homeaccount/miniconda3/envs/churn_pipeline/lib/python3.10/site-packages/airflow/models/baseoperator.py", line 401, in wrapper
    return func(self, *args, **kwargs)
  File "/Users/homeaccount/miniconda3/envs/churn_pipeline/lib/python3.10/site-packages/airflow/operators/python.py", line 235, in execute
    return_value = self.execute_callable()
  File "/Users/homeaccount/miniconda3/envs/churn_pipeline/lib/python3.10/site-packages/airflow/operators/python.py", line 252, in execute_callable
    return self.python_callable(*self.op_args, **self.op_kwargs)
  File "/Users/homeaccount/PycharmProjects/dmml/churn_prediction_pipeline/airflow_home/dags/.ipynb_checkpoints/airflow_dag-checkpoint.py", line 31, in ingestion
    run_cmd(["dvc", "add", "data/raw/telco_churn.csv", "data/raw/hf_bank_customer_support.csv"])
  File "/Users/homeaccount/PycharmProjects/dmml/churn_prediction_pipeline/airflow_home/dags/.ipynb_checkpoints/airflow_dag-checkpoint.py", line 16, in run_cmd
    subprocess.run(cmd, check=True)
  File "/Users/homeaccount/miniconda3/envs/churn_pipeline/lib/python3.10/subprocess.py", line 526, in run
    raise CalledProcessError(retcode, process.args,
subprocess.CalledProcessError: Command '['dvc', 'add', 'data/raw/telco_churn.csv', 'data/raw/hf_bank_customer_support.csv']' returned non-zero exit status 1.
[2025-08-24T18:13:50.213+0100] {taskinstance.py:1206} INFO - Marking task as UP_FOR_RETRY. dag_id=churn_pipeline_taskflow, task_id=ingestion, run_id=scheduled__2025-08-22T23:00:00+00:00, execution_date=20250822T230000, start_date=20250824T171347, end_date=20250824T171350
[2025-08-24T18:13:50.216+0100] {standard_task_runner.py:110} ERROR - Failed to execute job 19 for task ingestion (Command '['dvc', 'add', 'data/raw/telco_churn.csv', 'data/raw/hf_bank_customer_support.csv']' returned non-zero exit status 1.; 26334)
[2025-08-24T18:13:50.261+0100] {local_task_job_runner.py:243} INFO - Task exited with return code 1
[2025-08-24T18:13:50.270+0100] {taskinstance.py:3503} INFO - 0 downstream tasks scheduled from follow-on schedule check
[2025-08-24T18:13:50.270+0100] {local_task_job_runner.py:222} INFO - ::endgroup::
