[2025-08-24T17:44:22.959+0100] {local_task_job_runner.py:120} INFO - ::group::Pre task execution logs
[2025-08-24T17:44:22.966+0100] {taskinstance.py:2076} INFO - Dependencies all met for dep_context=non-requeueable deps ti=<TaskInstance: churn_pipeline_taskflow.ingestion scheduled__2025-08-22T23:00:00+00:00 [queued]>
[2025-08-24T17:44:22.968+0100] {taskinstance.py:2076} INFO - Dependencies all met for dep_context=requeueable deps ti=<TaskInstance: churn_pipeline_taskflow.ingestion scheduled__2025-08-22T23:00:00+00:00 [queued]>
[2025-08-24T17:44:22.968+0100] {taskinstance.py:2306} INFO - Starting attempt 5 of 6
[2025-08-24T17:44:22.971+0100] {taskinstance.py:2330} INFO - Executing <Task(_PythonDecoratedOperator): ingestion> on 2025-08-22 23:00:00+00:00
[2025-08-24T17:44:22.973+0100] {standard_task_runner.py:64} INFO - Started process 25752 to run task
[2025-08-24T17:44:22.976+0100] {standard_task_runner.py:90} INFO - Running: ['airflow', 'tasks', 'run', 'churn_pipeline_taskflow', 'ingestion', 'scheduled__2025-08-22T23:00:00+00:00', '--job-id', '11', '--raw', '--subdir', 'DAGS_FOLDER/airflow_dag.py', '--cfg-path', '/var/folders/c_/hn2ql5p54ylf2dsc72vqg5h40000gn/T/tmpnjvbn4rs']
[2025-08-24T17:44:22.977+0100] {standard_task_runner.py:91} INFO - Job 11: Subtask ingestion
[2025-08-24T17:44:22.991+0100] {task_command.py:426} INFO - Running <TaskInstance: churn_pipeline_taskflow.ingestion scheduled__2025-08-22T23:00:00+00:00 [running]> on host mac.communityfibre.co.uk
[2025-08-24T17:44:23.011+0100] {taskinstance.py:2648} INFO - Exporting env vars: AIRFLOW_CTX_DAG_OWNER='shivam' AIRFLOW_CTX_DAG_ID='churn_pipeline_taskflow' AIRFLOW_CTX_TASK_ID='ingestion' AIRFLOW_CTX_EXECUTION_DATE='2025-08-22T23:00:00+00:00' AIRFLOW_CTX_TRY_NUMBER='5' AIRFLOW_CTX_DAG_RUN_ID='scheduled__2025-08-22T23:00:00+00:00'
[2025-08-24T17:44:23.011+0100] {taskinstance.py:430} INFO - ::endgroup::
[2025-08-24T17:44:23.026+0100] {taskinstance.py:441} INFO - ::group::Post task execution logs
[2025-08-24T17:44:23.026+0100] {taskinstance.py:2905} ERROR - Task failed with exception
Traceback (most recent call last):
  File "/Users/homeaccount/miniconda3/envs/churn_pipeline/lib/python3.10/site-packages/airflow/models/taskinstance.py", line 465, in _execute_task
    result = _execute_callable(context=context, **execute_callable_kwargs)
  File "/Users/homeaccount/miniconda3/envs/churn_pipeline/lib/python3.10/site-packages/airflow/models/taskinstance.py", line 432, in _execute_callable
    return execute_callable(context=context, **execute_callable_kwargs)
  File "/Users/homeaccount/miniconda3/envs/churn_pipeline/lib/python3.10/site-packages/airflow/models/baseoperator.py", line 401, in wrapper
    return func(self, *args, **kwargs)
  File "/Users/homeaccount/miniconda3/envs/churn_pipeline/lib/python3.10/site-packages/airflow/decorators/base.py", line 265, in execute
    return_value = super().execute(context)
  File "/Users/homeaccount/miniconda3/envs/churn_pipeline/lib/python3.10/site-packages/airflow/models/baseoperator.py", line 401, in wrapper
    return func(self, *args, **kwargs)
  File "/Users/homeaccount/miniconda3/envs/churn_pipeline/lib/python3.10/site-packages/airflow/operators/python.py", line 235, in execute
    return_value = self.execute_callable()
  File "/Users/homeaccount/miniconda3/envs/churn_pipeline/lib/python3.10/site-packages/airflow/operators/python.py", line 252, in execute_callable
    return self.python_callable(*self.op_args, **self.op_kwargs)
  File "/Users/homeaccount/PycharmProjects/dmml/churn_prediction_pipeline/airflow_home/dags/airflow_dag.py", line 26, in ingestion
    run_cmd(["python", "scripts/ingest.py"])
  File "/Users/homeaccount/PycharmProjects/dmml/churn_prediction_pipeline/airflow_home/dags/airflow_dag.py", line 13, in run_cmd
    subprocess.run(cmd, check=True)
  File "/Users/homeaccount/miniconda3/envs/churn_pipeline/lib/python3.10/subprocess.py", line 526, in run
    raise CalledProcessError(retcode, process.args,
subprocess.CalledProcessError: Command '['python', 'scripts/ingest.py']' returned non-zero exit status 2.
[2025-08-24T17:44:23.029+0100] {taskinstance.py:1206} INFO - Marking task as UP_FOR_RETRY. dag_id=churn_pipeline_taskflow, task_id=ingestion, run_id=scheduled__2025-08-22T23:00:00+00:00, execution_date=20250822T230000, start_date=20250824T164422, end_date=20250824T164423
[2025-08-24T17:44:23.032+0100] {standard_task_runner.py:110} ERROR - Failed to execute job 11 for task ingestion (Command '['python', 'scripts/ingest.py']' returned non-zero exit status 2.; 25752)
[2025-08-24T17:44:23.037+0100] {local_task_job_runner.py:243} INFO - Task exited with return code 1
[2025-08-24T17:44:23.044+0100] {taskinstance.py:3503} INFO - 0 downstream tasks scheduled from follow-on schedule check
[2025-08-24T17:44:23.044+0100] {local_task_job_runner.py:222} INFO - ::endgroup::
[2025-08-24T18:10:45.582+0100] {local_task_job_runner.py:120} INFO - ::group::Pre task execution logs
[2025-08-24T18:10:45.590+0100] {taskinstance.py:2076} INFO - Dependencies all met for dep_context=non-requeueable deps ti=<TaskInstance: churn_pipeline_taskflow.ingestion scheduled__2025-08-22T23:00:00+00:00 [queued]>
[2025-08-24T18:10:45.592+0100] {taskinstance.py:2076} INFO - Dependencies all met for dep_context=requeueable deps ti=<TaskInstance: churn_pipeline_taskflow.ingestion scheduled__2025-08-22T23:00:00+00:00 [queued]>
[2025-08-24T18:10:45.592+0100] {taskinstance.py:2306} INFO - Starting attempt 5 of 6
[2025-08-24T18:10:45.596+0100] {taskinstance.py:2330} INFO - Executing <Task(_PythonDecoratedOperator): ingestion> on 2025-08-22 23:00:00+00:00
[2025-08-24T18:10:45.598+0100] {standard_task_runner.py:64} INFO - Started process 26260 to run task
[2025-08-24T18:10:45.601+0100] {standard_task_runner.py:90} INFO - Running: ['airflow', 'tasks', 'run', 'churn_pipeline_taskflow', 'ingestion', 'scheduled__2025-08-22T23:00:00+00:00', '--job-id', '25', '--raw', '--subdir', 'DAGS_FOLDER/.ipynb_checkpoints/airflow_dag-checkpoint.py', '--cfg-path', '/var/folders/c_/hn2ql5p54ylf2dsc72vqg5h40000gn/T/tmpcf0cqbyn']
[2025-08-24T18:10:45.602+0100] {standard_task_runner.py:91} INFO - Job 25: Subtask ingestion
[2025-08-24T18:10:45.617+0100] {task_command.py:426} INFO - Running <TaskInstance: churn_pipeline_taskflow.ingestion scheduled__2025-08-22T23:00:00+00:00 [running]> on host mac.communityfibre.co.uk
[2025-08-24T18:10:45.637+0100] {taskinstance.py:2648} INFO - Exporting env vars: AIRFLOW_CTX_DAG_OWNER='shivam' AIRFLOW_CTX_DAG_ID='churn_pipeline_taskflow' AIRFLOW_CTX_TASK_ID='ingestion' AIRFLOW_CTX_EXECUTION_DATE='2025-08-22T23:00:00+00:00' AIRFLOW_CTX_TRY_NUMBER='5' AIRFLOW_CTX_DAG_RUN_ID='scheduled__2025-08-22T23:00:00+00:00'
[2025-08-24T18:10:45.637+0100] {taskinstance.py:430} INFO - ::endgroup::
[2025-08-24T18:10:48.822+0100] {taskinstance.py:441} INFO - ::group::Post task execution logs
[2025-08-24T18:10:48.823+0100] {taskinstance.py:2905} ERROR - Task failed with exception
Traceback (most recent call last):
  File "/Users/homeaccount/miniconda3/envs/churn_pipeline/lib/python3.10/site-packages/airflow/models/taskinstance.py", line 465, in _execute_task
    result = _execute_callable(context=context, **execute_callable_kwargs)
  File "/Users/homeaccount/miniconda3/envs/churn_pipeline/lib/python3.10/site-packages/airflow/models/taskinstance.py", line 432, in _execute_callable
    return execute_callable(context=context, **execute_callable_kwargs)
  File "/Users/homeaccount/miniconda3/envs/churn_pipeline/lib/python3.10/site-packages/airflow/models/baseoperator.py", line 401, in wrapper
    return func(self, *args, **kwargs)
  File "/Users/homeaccount/miniconda3/envs/churn_pipeline/lib/python3.10/site-packages/airflow/decorators/base.py", line 265, in execute
    return_value = super().execute(context)
  File "/Users/homeaccount/miniconda3/envs/churn_pipeline/lib/python3.10/site-packages/airflow/models/baseoperator.py", line 401, in wrapper
    return func(self, *args, **kwargs)
  File "/Users/homeaccount/miniconda3/envs/churn_pipeline/lib/python3.10/site-packages/airflow/operators/python.py", line 235, in execute
    return_value = self.execute_callable()
  File "/Users/homeaccount/miniconda3/envs/churn_pipeline/lib/python3.10/site-packages/airflow/operators/python.py", line 252, in execute_callable
    return self.python_callable(*self.op_args, **self.op_kwargs)
  File "/Users/homeaccount/PycharmProjects/dmml/churn_prediction_pipeline/airflow_home/dags/.ipynb_checkpoints/airflow_dag-checkpoint.py", line 30, in ingestion
    run_cmd(["dvc", "add", "data/raw/telco_churn.csv", "data/raw/hf_bank_customer_support.csv"])
  File "/Users/homeaccount/PycharmProjects/dmml/churn_prediction_pipeline/airflow_home/dags/.ipynb_checkpoints/airflow_dag-checkpoint.py", line 16, in run_cmd
    subprocess.run(cmd, check=True)
  File "/Users/homeaccount/miniconda3/envs/churn_pipeline/lib/python3.10/subprocess.py", line 526, in run
    raise CalledProcessError(retcode, process.args,
subprocess.CalledProcessError: Command '['dvc', 'add', 'data/raw/telco_churn.csv', 'data/raw/hf_bank_customer_support.csv']' returned non-zero exit status 1.
[2025-08-24T18:10:48.827+0100] {taskinstance.py:1206} INFO - Marking task as UP_FOR_RETRY. dag_id=churn_pipeline_taskflow, task_id=ingestion, run_id=scheduled__2025-08-22T23:00:00+00:00, execution_date=20250822T230000, start_date=20250824T171045, end_date=20250824T171048
[2025-08-24T18:10:48.831+0100] {standard_task_runner.py:110} ERROR - Failed to execute job 25 for task ingestion (Command '['dvc', 'add', 'data/raw/telco_churn.csv', 'data/raw/hf_bank_customer_support.csv']' returned non-zero exit status 1.; 26260)
[2025-08-24T18:10:48.851+0100] {local_task_job_runner.py:243} INFO - Task exited with return code 1
[2025-08-24T18:10:48.859+0100] {taskinstance.py:3503} INFO - 0 downstream tasks scheduled from follow-on schedule check
[2025-08-24T18:10:48.859+0100] {local_task_job_runner.py:222} INFO - ::endgroup::
[2025-08-24T18:14:14.602+0100] {local_task_job_runner.py:120} INFO - ::group::Pre task execution logs
[2025-08-24T18:14:14.610+0100] {taskinstance.py:2076} INFO - Dependencies all met for dep_context=non-requeueable deps ti=<TaskInstance: churn_pipeline_taskflow.ingestion scheduled__2025-08-22T23:00:00+00:00 [queued]>
[2025-08-24T18:14:14.612+0100] {taskinstance.py:2076} INFO - Dependencies all met for dep_context=requeueable deps ti=<TaskInstance: churn_pipeline_taskflow.ingestion scheduled__2025-08-22T23:00:00+00:00 [queued]>
[2025-08-24T18:14:14.613+0100] {taskinstance.py:2306} INFO - Starting attempt 5 of 6
[2025-08-24T18:14:14.617+0100] {taskinstance.py:2330} INFO - Executing <Task(_PythonDecoratedOperator): ingestion> on 2025-08-22 23:00:00+00:00
[2025-08-24T18:14:14.619+0100] {standard_task_runner.py:64} INFO - Started process 26369 to run task
[2025-08-24T18:14:14.622+0100] {standard_task_runner.py:90} INFO - Running: ['airflow', 'tasks', 'run', 'churn_pipeline_taskflow', 'ingestion', 'scheduled__2025-08-22T23:00:00+00:00', '--job-id', '25', '--raw', '--subdir', 'DAGS_FOLDER/.ipynb_checkpoints/airflow_dag-checkpoint.py', '--cfg-path', '/var/folders/c_/hn2ql5p54ylf2dsc72vqg5h40000gn/T/tmpi9s_4vn2']
[2025-08-24T18:14:14.623+0100] {standard_task_runner.py:91} INFO - Job 25: Subtask ingestion
[2025-08-24T18:14:14.638+0100] {task_command.py:426} INFO - Running <TaskInstance: churn_pipeline_taskflow.ingestion scheduled__2025-08-22T23:00:00+00:00 [running]> on host mac.communityfibre.co.uk
[2025-08-24T18:14:14.657+0100] {taskinstance.py:2648} INFO - Exporting env vars: AIRFLOW_CTX_DAG_OWNER='shivam' AIRFLOW_CTX_DAG_ID='churn_pipeline_taskflow' AIRFLOW_CTX_TASK_ID='ingestion' AIRFLOW_CTX_EXECUTION_DATE='2025-08-22T23:00:00+00:00' AIRFLOW_CTX_TRY_NUMBER='5' AIRFLOW_CTX_DAG_RUN_ID='scheduled__2025-08-22T23:00:00+00:00'
[2025-08-24T18:14:14.658+0100] {taskinstance.py:430} INFO - ::endgroup::
[2025-08-24T18:14:14.658+0100] {logging_mixin.py:188} INFO - /Users/homeaccount/PycharmProjects/dmml/churn_prediction_pipeline
[2025-08-24T18:14:17.720+0100] {taskinstance.py:441} INFO - ::group::Post task execution logs
[2025-08-24T18:14:17.721+0100] {taskinstance.py:2905} ERROR - Task failed with exception
Traceback (most recent call last):
  File "/Users/homeaccount/miniconda3/envs/churn_pipeline/lib/python3.10/site-packages/airflow/models/taskinstance.py", line 465, in _execute_task
    result = _execute_callable(context=context, **execute_callable_kwargs)
  File "/Users/homeaccount/miniconda3/envs/churn_pipeline/lib/python3.10/site-packages/airflow/models/taskinstance.py", line 432, in _execute_callable
    return execute_callable(context=context, **execute_callable_kwargs)
  File "/Users/homeaccount/miniconda3/envs/churn_pipeline/lib/python3.10/site-packages/airflow/models/baseoperator.py", line 401, in wrapper
    return func(self, *args, **kwargs)
  File "/Users/homeaccount/miniconda3/envs/churn_pipeline/lib/python3.10/site-packages/airflow/decorators/base.py", line 265, in execute
    return_value = super().execute(context)
  File "/Users/homeaccount/miniconda3/envs/churn_pipeline/lib/python3.10/site-packages/airflow/models/baseoperator.py", line 401, in wrapper
    return func(self, *args, **kwargs)
  File "/Users/homeaccount/miniconda3/envs/churn_pipeline/lib/python3.10/site-packages/airflow/operators/python.py", line 235, in execute
    return_value = self.execute_callable()
  File "/Users/homeaccount/miniconda3/envs/churn_pipeline/lib/python3.10/site-packages/airflow/operators/python.py", line 252, in execute_callable
    return self.python_callable(*self.op_args, **self.op_kwargs)
  File "/Users/homeaccount/PycharmProjects/dmml/churn_prediction_pipeline/airflow_home/dags/.ipynb_checkpoints/airflow_dag-checkpoint.py", line 31, in ingestion
    run_cmd(["dvc", "add", "data/raw/telco_churn.csv", "data/raw/hf_bank_customer_support.csv"])
  File "/Users/homeaccount/PycharmProjects/dmml/churn_prediction_pipeline/airflow_home/dags/.ipynb_checkpoints/airflow_dag-checkpoint.py", line 16, in run_cmd
    subprocess.run(cmd, check=True)
  File "/Users/homeaccount/miniconda3/envs/churn_pipeline/lib/python3.10/subprocess.py", line 526, in run
    raise CalledProcessError(retcode, process.args,
subprocess.CalledProcessError: Command '['dvc', 'add', 'data/raw/telco_churn.csv', 'data/raw/hf_bank_customer_support.csv']' returned non-zero exit status 1.
[2025-08-24T18:14:17.724+0100] {taskinstance.py:1206} INFO - Marking task as UP_FOR_RETRY. dag_id=churn_pipeline_taskflow, task_id=ingestion, run_id=scheduled__2025-08-22T23:00:00+00:00, execution_date=20250822T230000, start_date=20250824T171414, end_date=20250824T171417
[2025-08-24T18:14:17.728+0100] {standard_task_runner.py:110} ERROR - Failed to execute job 25 for task ingestion (Command '['dvc', 'add', 'data/raw/telco_churn.csv', 'data/raw/hf_bank_customer_support.csv']' returned non-zero exit status 1.; 26369)
[2025-08-24T18:14:17.759+0100] {local_task_job_runner.py:243} INFO - Task exited with return code 1
[2025-08-24T18:14:17.767+0100] {taskinstance.py:3503} INFO - 0 downstream tasks scheduled from follow-on schedule check
[2025-08-24T18:14:17.767+0100] {local_task_job_runner.py:222} INFO - ::endgroup::
