[2025-08-24T17:44:28.825+0100] {local_task_job_runner.py:120} INFO - ::group::Pre task execution logs
[2025-08-24T17:44:28.831+0100] {taskinstance.py:2076} INFO - Dependencies all met for dep_context=non-requeueable deps ti=<TaskInstance: churn_pipeline_taskflow.ingestion scheduled__2025-08-22T23:00:00+00:00 [queued]>
[2025-08-24T17:44:28.833+0100] {taskinstance.py:2076} INFO - Dependencies all met for dep_context=requeueable deps ti=<TaskInstance: churn_pipeline_taskflow.ingestion scheduled__2025-08-22T23:00:00+00:00 [queued]>
[2025-08-24T17:44:28.833+0100] {taskinstance.py:2306} INFO - Starting attempt 6 of 6
[2025-08-24T17:44:28.837+0100] {taskinstance.py:2330} INFO - Executing <Task(_PythonDecoratedOperator): ingestion> on 2025-08-22 23:00:00+00:00
[2025-08-24T17:44:28.839+0100] {standard_task_runner.py:64} INFO - Started process 25758 to run task
[2025-08-24T17:44:28.841+0100] {standard_task_runner.py:90} INFO - Running: ['airflow', 'tasks', 'run', 'churn_pipeline_taskflow', 'ingestion', 'scheduled__2025-08-22T23:00:00+00:00', '--job-id', '13', '--raw', '--subdir', 'DAGS_FOLDER/airflow_dag.py', '--cfg-path', '/var/folders/c_/hn2ql5p54ylf2dsc72vqg5h40000gn/T/tmp5vqie_ap']
[2025-08-24T17:44:28.842+0100] {standard_task_runner.py:91} INFO - Job 13: Subtask ingestion
[2025-08-24T17:44:28.855+0100] {task_command.py:426} INFO - Running <TaskInstance: churn_pipeline_taskflow.ingestion scheduled__2025-08-22T23:00:00+00:00 [running]> on host mac.communityfibre.co.uk
[2025-08-24T17:44:28.874+0100] {taskinstance.py:2648} INFO - Exporting env vars: AIRFLOW_CTX_DAG_OWNER='shivam' AIRFLOW_CTX_DAG_ID='churn_pipeline_taskflow' AIRFLOW_CTX_TASK_ID='ingestion' AIRFLOW_CTX_EXECUTION_DATE='2025-08-22T23:00:00+00:00' AIRFLOW_CTX_TRY_NUMBER='6' AIRFLOW_CTX_DAG_RUN_ID='scheduled__2025-08-22T23:00:00+00:00'
[2025-08-24T17:44:28.874+0100] {taskinstance.py:430} INFO - ::endgroup::
[2025-08-24T17:44:28.887+0100] {taskinstance.py:441} INFO - ::group::Post task execution logs
[2025-08-24T17:44:28.888+0100] {taskinstance.py:2905} ERROR - Task failed with exception
Traceback (most recent call last):
  File "/Users/homeaccount/miniconda3/envs/churn_pipeline/lib/python3.10/site-packages/airflow/models/taskinstance.py", line 465, in _execute_task
    result = _execute_callable(context=context, **execute_callable_kwargs)
  File "/Users/homeaccount/miniconda3/envs/churn_pipeline/lib/python3.10/site-packages/airflow/models/taskinstance.py", line 432, in _execute_callable
    return execute_callable(context=context, **execute_callable_kwargs)
  File "/Users/homeaccount/miniconda3/envs/churn_pipeline/lib/python3.10/site-packages/airflow/models/baseoperator.py", line 401, in wrapper
    return func(self, *args, **kwargs)
  File "/Users/homeaccount/miniconda3/envs/churn_pipeline/lib/python3.10/site-packages/airflow/decorators/base.py", line 265, in execute
    return_value = super().execute(context)
  File "/Users/homeaccount/miniconda3/envs/churn_pipeline/lib/python3.10/site-packages/airflow/models/baseoperator.py", line 401, in wrapper
    return func(self, *args, **kwargs)
  File "/Users/homeaccount/miniconda3/envs/churn_pipeline/lib/python3.10/site-packages/airflow/operators/python.py", line 235, in execute
    return_value = self.execute_callable()
  File "/Users/homeaccount/miniconda3/envs/churn_pipeline/lib/python3.10/site-packages/airflow/operators/python.py", line 252, in execute_callable
    return self.python_callable(*self.op_args, **self.op_kwargs)
  File "/Users/homeaccount/PycharmProjects/dmml/churn_prediction_pipeline/airflow_home/dags/airflow_dag.py", line 26, in ingestion
    run_cmd(["python", "scripts/ingest.py"])
  File "/Users/homeaccount/PycharmProjects/dmml/churn_prediction_pipeline/airflow_home/dags/airflow_dag.py", line 13, in run_cmd
    subprocess.run(cmd, check=True)
  File "/Users/homeaccount/miniconda3/envs/churn_pipeline/lib/python3.10/subprocess.py", line 526, in run
    raise CalledProcessError(retcode, process.args,
subprocess.CalledProcessError: Command '['python', 'scripts/ingest.py']' returned non-zero exit status 2.
[2025-08-24T17:44:28.891+0100] {taskinstance.py:1206} INFO - Marking task as FAILED. dag_id=churn_pipeline_taskflow, task_id=ingestion, run_id=scheduled__2025-08-22T23:00:00+00:00, execution_date=20250822T230000, start_date=20250824T164428, end_date=20250824T164428
[2025-08-24T17:44:28.894+0100] {standard_task_runner.py:110} ERROR - Failed to execute job 13 for task ingestion (Command '['python', 'scripts/ingest.py']' returned non-zero exit status 2.; 25758)
[2025-08-24T17:44:28.903+0100] {local_task_job_runner.py:243} INFO - Task exited with return code 1
[2025-08-24T17:44:28.910+0100] {taskinstance.py:3503} INFO - 0 downstream tasks scheduled from follow-on schedule check
[2025-08-24T17:44:28.911+0100] {local_task_job_runner.py:222} INFO - ::endgroup::
[2025-08-24T18:10:55.153+0100] {local_task_job_runner.py:120} INFO - ::group::Pre task execution logs
[2025-08-24T18:10:55.160+0100] {taskinstance.py:2076} INFO - Dependencies all met for dep_context=non-requeueable deps ti=<TaskInstance: churn_pipeline_taskflow.ingestion scheduled__2025-08-22T23:00:00+00:00 [queued]>
[2025-08-24T18:10:55.162+0100] {taskinstance.py:2076} INFO - Dependencies all met for dep_context=requeueable deps ti=<TaskInstance: churn_pipeline_taskflow.ingestion scheduled__2025-08-22T23:00:00+00:00 [queued]>
[2025-08-24T18:10:55.162+0100] {taskinstance.py:2306} INFO - Starting attempt 6 of 6
[2025-08-24T18:10:55.166+0100] {taskinstance.py:2330} INFO - Executing <Task(_PythonDecoratedOperator): ingestion> on 2025-08-22 23:00:00+00:00
[2025-08-24T18:10:55.168+0100] {standard_task_runner.py:64} INFO - Started process 26273 to run task
[2025-08-24T18:10:55.171+0100] {standard_task_runner.py:90} INFO - Running: ['airflow', 'tasks', 'run', 'churn_pipeline_taskflow', 'ingestion', 'scheduled__2025-08-22T23:00:00+00:00', '--job-id', '27', '--raw', '--subdir', 'DAGS_FOLDER/.ipynb_checkpoints/airflow_dag-checkpoint.py', '--cfg-path', '/var/folders/c_/hn2ql5p54ylf2dsc72vqg5h40000gn/T/tmpvbi4urm9']
[2025-08-24T18:10:55.172+0100] {standard_task_runner.py:91} INFO - Job 27: Subtask ingestion
[2025-08-24T18:10:55.186+0100] {task_command.py:426} INFO - Running <TaskInstance: churn_pipeline_taskflow.ingestion scheduled__2025-08-22T23:00:00+00:00 [running]> on host mac.communityfibre.co.uk
[2025-08-24T18:10:55.205+0100] {taskinstance.py:2648} INFO - Exporting env vars: AIRFLOW_CTX_DAG_OWNER='shivam' AIRFLOW_CTX_DAG_ID='churn_pipeline_taskflow' AIRFLOW_CTX_TASK_ID='ingestion' AIRFLOW_CTX_EXECUTION_DATE='2025-08-22T23:00:00+00:00' AIRFLOW_CTX_TRY_NUMBER='6' AIRFLOW_CTX_DAG_RUN_ID='scheduled__2025-08-22T23:00:00+00:00'
[2025-08-24T18:10:55.206+0100] {taskinstance.py:430} INFO - ::endgroup::
[2025-08-24T18:10:58.381+0100] {taskinstance.py:441} INFO - ::group::Post task execution logs
[2025-08-24T18:10:58.382+0100] {taskinstance.py:2905} ERROR - Task failed with exception
Traceback (most recent call last):
  File "/Users/homeaccount/miniconda3/envs/churn_pipeline/lib/python3.10/site-packages/airflow/models/taskinstance.py", line 465, in _execute_task
    result = _execute_callable(context=context, **execute_callable_kwargs)
  File "/Users/homeaccount/miniconda3/envs/churn_pipeline/lib/python3.10/site-packages/airflow/models/taskinstance.py", line 432, in _execute_callable
    return execute_callable(context=context, **execute_callable_kwargs)
  File "/Users/homeaccount/miniconda3/envs/churn_pipeline/lib/python3.10/site-packages/airflow/models/baseoperator.py", line 401, in wrapper
    return func(self, *args, **kwargs)
  File "/Users/homeaccount/miniconda3/envs/churn_pipeline/lib/python3.10/site-packages/airflow/decorators/base.py", line 265, in execute
    return_value = super().execute(context)
  File "/Users/homeaccount/miniconda3/envs/churn_pipeline/lib/python3.10/site-packages/airflow/models/baseoperator.py", line 401, in wrapper
    return func(self, *args, **kwargs)
  File "/Users/homeaccount/miniconda3/envs/churn_pipeline/lib/python3.10/site-packages/airflow/operators/python.py", line 235, in execute
    return_value = self.execute_callable()
  File "/Users/homeaccount/miniconda3/envs/churn_pipeline/lib/python3.10/site-packages/airflow/operators/python.py", line 252, in execute_callable
    return self.python_callable(*self.op_args, **self.op_kwargs)
  File "/Users/homeaccount/PycharmProjects/dmml/churn_prediction_pipeline/airflow_home/dags/.ipynb_checkpoints/airflow_dag-checkpoint.py", line 30, in ingestion
    run_cmd(["dvc", "add", "data/raw/telco_churn.csv", "data/raw/hf_bank_customer_support.csv"])
  File "/Users/homeaccount/PycharmProjects/dmml/churn_prediction_pipeline/airflow_home/dags/.ipynb_checkpoints/airflow_dag-checkpoint.py", line 16, in run_cmd
    subprocess.run(cmd, check=True)
  File "/Users/homeaccount/miniconda3/envs/churn_pipeline/lib/python3.10/subprocess.py", line 526, in run
    raise CalledProcessError(retcode, process.args,
subprocess.CalledProcessError: Command '['dvc', 'add', 'data/raw/telco_churn.csv', 'data/raw/hf_bank_customer_support.csv']' returned non-zero exit status 1.
[2025-08-24T18:10:58.385+0100] {taskinstance.py:1206} INFO - Marking task as FAILED. dag_id=churn_pipeline_taskflow, task_id=ingestion, run_id=scheduled__2025-08-22T23:00:00+00:00, execution_date=20250822T230000, start_date=20250824T171055, end_date=20250824T171058
[2025-08-24T18:10:58.389+0100] {standard_task_runner.py:110} ERROR - Failed to execute job 27 for task ingestion (Command '['dvc', 'add', 'data/raw/telco_churn.csv', 'data/raw/hf_bank_customer_support.csv']' returned non-zero exit status 1.; 26273)
[2025-08-24T18:10:58.396+0100] {local_task_job_runner.py:243} INFO - Task exited with return code 1
[2025-08-24T18:10:58.403+0100] {taskinstance.py:3503} INFO - 0 downstream tasks scheduled from follow-on schedule check
[2025-08-24T18:10:58.404+0100] {local_task_job_runner.py:222} INFO - ::endgroup::
[2025-08-24T18:14:23.557+0100] {local_task_job_runner.py:120} INFO - ::group::Pre task execution logs
[2025-08-24T18:14:23.563+0100] {taskinstance.py:2076} INFO - Dependencies all met for dep_context=non-requeueable deps ti=<TaskInstance: churn_pipeline_taskflow.ingestion scheduled__2025-08-22T23:00:00+00:00 [queued]>
[2025-08-24T18:14:23.565+0100] {taskinstance.py:2076} INFO - Dependencies all met for dep_context=requeueable deps ti=<TaskInstance: churn_pipeline_taskflow.ingestion scheduled__2025-08-22T23:00:00+00:00 [queued]>
[2025-08-24T18:14:23.565+0100] {taskinstance.py:2306} INFO - Starting attempt 6 of 6
[2025-08-24T18:14:23.569+0100] {taskinstance.py:2330} INFO - Executing <Task(_PythonDecoratedOperator): ingestion> on 2025-08-22 23:00:00+00:00
[2025-08-24T18:14:23.571+0100] {standard_task_runner.py:64} INFO - Started process 26381 to run task
[2025-08-24T18:14:23.574+0100] {standard_task_runner.py:90} INFO - Running: ['airflow', 'tasks', 'run', 'churn_pipeline_taskflow', 'ingestion', 'scheduled__2025-08-22T23:00:00+00:00', '--job-id', '27', '--raw', '--subdir', 'DAGS_FOLDER/.ipynb_checkpoints/airflow_dag-checkpoint.py', '--cfg-path', '/var/folders/c_/hn2ql5p54ylf2dsc72vqg5h40000gn/T/tmpg29thri_']
[2025-08-24T18:14:23.575+0100] {standard_task_runner.py:91} INFO - Job 27: Subtask ingestion
[2025-08-24T18:14:23.588+0100] {task_command.py:426} INFO - Running <TaskInstance: churn_pipeline_taskflow.ingestion scheduled__2025-08-22T23:00:00+00:00 [running]> on host mac.communityfibre.co.uk
[2025-08-24T18:14:23.607+0100] {taskinstance.py:2648} INFO - Exporting env vars: AIRFLOW_CTX_DAG_OWNER='shivam' AIRFLOW_CTX_DAG_ID='churn_pipeline_taskflow' AIRFLOW_CTX_TASK_ID='ingestion' AIRFLOW_CTX_EXECUTION_DATE='2025-08-22T23:00:00+00:00' AIRFLOW_CTX_TRY_NUMBER='6' AIRFLOW_CTX_DAG_RUN_ID='scheduled__2025-08-22T23:00:00+00:00'
[2025-08-24T18:14:23.607+0100] {taskinstance.py:430} INFO - ::endgroup::
[2025-08-24T18:14:23.608+0100] {logging_mixin.py:188} INFO - /Users/homeaccount/PycharmProjects/dmml/churn_prediction_pipeline
[2025-08-24T18:14:26.546+0100] {taskinstance.py:441} INFO - ::group::Post task execution logs
[2025-08-24T18:14:26.547+0100] {taskinstance.py:2905} ERROR - Task failed with exception
Traceback (most recent call last):
  File "/Users/homeaccount/miniconda3/envs/churn_pipeline/lib/python3.10/site-packages/airflow/models/taskinstance.py", line 465, in _execute_task
    result = _execute_callable(context=context, **execute_callable_kwargs)
  File "/Users/homeaccount/miniconda3/envs/churn_pipeline/lib/python3.10/site-packages/airflow/models/taskinstance.py", line 432, in _execute_callable
    return execute_callable(context=context, **execute_callable_kwargs)
  File "/Users/homeaccount/miniconda3/envs/churn_pipeline/lib/python3.10/site-packages/airflow/models/baseoperator.py", line 401, in wrapper
    return func(self, *args, **kwargs)
  File "/Users/homeaccount/miniconda3/envs/churn_pipeline/lib/python3.10/site-packages/airflow/decorators/base.py", line 265, in execute
    return_value = super().execute(context)
  File "/Users/homeaccount/miniconda3/envs/churn_pipeline/lib/python3.10/site-packages/airflow/models/baseoperator.py", line 401, in wrapper
    return func(self, *args, **kwargs)
  File "/Users/homeaccount/miniconda3/envs/churn_pipeline/lib/python3.10/site-packages/airflow/operators/python.py", line 235, in execute
    return_value = self.execute_callable()
  File "/Users/homeaccount/miniconda3/envs/churn_pipeline/lib/python3.10/site-packages/airflow/operators/python.py", line 252, in execute_callable
    return self.python_callable(*self.op_args, **self.op_kwargs)
  File "/Users/homeaccount/PycharmProjects/dmml/churn_prediction_pipeline/airflow_home/dags/.ipynb_checkpoints/airflow_dag-checkpoint.py", line 31, in ingestion
    run_cmd(["dvc", "add", "data/raw/telco_churn.csv", "data/raw/hf_bank_customer_support.csv"])
  File "/Users/homeaccount/PycharmProjects/dmml/churn_prediction_pipeline/airflow_home/dags/.ipynb_checkpoints/airflow_dag-checkpoint.py", line 16, in run_cmd
    subprocess.run(cmd, check=True)
  File "/Users/homeaccount/miniconda3/envs/churn_pipeline/lib/python3.10/subprocess.py", line 526, in run
    raise CalledProcessError(retcode, process.args,
subprocess.CalledProcessError: Command '['dvc', 'add', 'data/raw/telco_churn.csv', 'data/raw/hf_bank_customer_support.csv']' returned non-zero exit status 1.
[2025-08-24T18:14:26.550+0100] {taskinstance.py:1206} INFO - Marking task as FAILED. dag_id=churn_pipeline_taskflow, task_id=ingestion, run_id=scheduled__2025-08-22T23:00:00+00:00, execution_date=20250822T230000, start_date=20250824T171423, end_date=20250824T171426
[2025-08-24T18:14:26.553+0100] {standard_task_runner.py:110} ERROR - Failed to execute job 27 for task ingestion (Command '['dvc', 'add', 'data/raw/telco_churn.csv', 'data/raw/hf_bank_customer_support.csv']' returned non-zero exit status 1.; 26381)
[2025-08-24T18:14:26.577+0100] {local_task_job_runner.py:243} INFO - Task exited with return code 1
[2025-08-24T18:14:26.584+0100] {taskinstance.py:3503} INFO - 0 downstream tasks scheduled from follow-on schedule check
[2025-08-24T18:14:26.586+0100] {local_task_job_runner.py:222} INFO - ::endgroup::
