[2025-08-24T17:44:17.052+0100] {local_task_job_runner.py:120} INFO - ::group::Pre task execution logs
[2025-08-24T17:44:17.059+0100] {taskinstance.py:2076} INFO - Dependencies all met for dep_context=non-requeueable deps ti=<TaskInstance: churn_pipeline_taskflow.ingestion scheduled__2025-08-22T23:00:00+00:00 [queued]>
[2025-08-24T17:44:17.061+0100] {taskinstance.py:2076} INFO - Dependencies all met for dep_context=requeueable deps ti=<TaskInstance: churn_pipeline_taskflow.ingestion scheduled__2025-08-22T23:00:00+00:00 [queued]>
[2025-08-24T17:44:17.061+0100] {taskinstance.py:2306} INFO - Starting attempt 4 of 6
[2025-08-24T17:44:17.065+0100] {taskinstance.py:2330} INFO - Executing <Task(_PythonDecoratedOperator): ingestion> on 2025-08-22 23:00:00+00:00
[2025-08-24T17:44:17.067+0100] {standard_task_runner.py:64} INFO - Started process 25746 to run task
[2025-08-24T17:44:17.070+0100] {standard_task_runner.py:90} INFO - Running: ['airflow', 'tasks', 'run', 'churn_pipeline_taskflow', 'ingestion', 'scheduled__2025-08-22T23:00:00+00:00', '--job-id', '9', '--raw', '--subdir', 'DAGS_FOLDER/airflow_dag.py', '--cfg-path', '/var/folders/c_/hn2ql5p54ylf2dsc72vqg5h40000gn/T/tmppfxu1zvm']
[2025-08-24T17:44:17.071+0100] {standard_task_runner.py:91} INFO - Job 9: Subtask ingestion
[2025-08-24T17:44:17.086+0100] {task_command.py:426} INFO - Running <TaskInstance: churn_pipeline_taskflow.ingestion scheduled__2025-08-22T23:00:00+00:00 [running]> on host mac.communityfibre.co.uk
[2025-08-24T17:44:17.107+0100] {taskinstance.py:2648} INFO - Exporting env vars: AIRFLOW_CTX_DAG_OWNER='shivam' AIRFLOW_CTX_DAG_ID='churn_pipeline_taskflow' AIRFLOW_CTX_TASK_ID='ingestion' AIRFLOW_CTX_EXECUTION_DATE='2025-08-22T23:00:00+00:00' AIRFLOW_CTX_TRY_NUMBER='4' AIRFLOW_CTX_DAG_RUN_ID='scheduled__2025-08-22T23:00:00+00:00'
[2025-08-24T17:44:17.107+0100] {taskinstance.py:430} INFO - ::endgroup::
[2025-08-24T17:44:17.122+0100] {taskinstance.py:441} INFO - ::group::Post task execution logs
[2025-08-24T17:44:17.123+0100] {taskinstance.py:2905} ERROR - Task failed with exception
Traceback (most recent call last):
  File "/Users/homeaccount/miniconda3/envs/churn_pipeline/lib/python3.10/site-packages/airflow/models/taskinstance.py", line 465, in _execute_task
    result = _execute_callable(context=context, **execute_callable_kwargs)
  File "/Users/homeaccount/miniconda3/envs/churn_pipeline/lib/python3.10/site-packages/airflow/models/taskinstance.py", line 432, in _execute_callable
    return execute_callable(context=context, **execute_callable_kwargs)
  File "/Users/homeaccount/miniconda3/envs/churn_pipeline/lib/python3.10/site-packages/airflow/models/baseoperator.py", line 401, in wrapper
    return func(self, *args, **kwargs)
  File "/Users/homeaccount/miniconda3/envs/churn_pipeline/lib/python3.10/site-packages/airflow/decorators/base.py", line 265, in execute
    return_value = super().execute(context)
  File "/Users/homeaccount/miniconda3/envs/churn_pipeline/lib/python3.10/site-packages/airflow/models/baseoperator.py", line 401, in wrapper
    return func(self, *args, **kwargs)
  File "/Users/homeaccount/miniconda3/envs/churn_pipeline/lib/python3.10/site-packages/airflow/operators/python.py", line 235, in execute
    return_value = self.execute_callable()
  File "/Users/homeaccount/miniconda3/envs/churn_pipeline/lib/python3.10/site-packages/airflow/operators/python.py", line 252, in execute_callable
    return self.python_callable(*self.op_args, **self.op_kwargs)
  File "/Users/homeaccount/PycharmProjects/dmml/churn_prediction_pipeline/airflow_home/dags/airflow_dag.py", line 26, in ingestion
    run_cmd(["python", "scripts/ingest.py"])
  File "/Users/homeaccount/PycharmProjects/dmml/churn_prediction_pipeline/airflow_home/dags/airflow_dag.py", line 13, in run_cmd
    subprocess.run(cmd, check=True)
  File "/Users/homeaccount/miniconda3/envs/churn_pipeline/lib/python3.10/subprocess.py", line 526, in run
    raise CalledProcessError(retcode, process.args,
subprocess.CalledProcessError: Command '['python', 'scripts/ingest.py']' returned non-zero exit status 2.
[2025-08-24T17:44:17.126+0100] {taskinstance.py:1206} INFO - Marking task as UP_FOR_RETRY. dag_id=churn_pipeline_taskflow, task_id=ingestion, run_id=scheduled__2025-08-22T23:00:00+00:00, execution_date=20250822T230000, start_date=20250824T164417, end_date=20250824T164417
[2025-08-24T17:44:17.129+0100] {standard_task_runner.py:110} ERROR - Failed to execute job 9 for task ingestion (Command '['python', 'scripts/ingest.py']' returned non-zero exit status 2.; 25746)
[2025-08-24T17:44:17.177+0100] {local_task_job_runner.py:243} INFO - Task exited with return code 1
[2025-08-24T17:44:17.185+0100] {taskinstance.py:3503} INFO - 0 downstream tasks scheduled from follow-on schedule check
[2025-08-24T17:44:17.185+0100] {local_task_job_runner.py:222} INFO - ::endgroup::
[2025-08-24T18:10:36.695+0100] {local_task_job_runner.py:120} INFO - ::group::Pre task execution logs
[2025-08-24T18:10:36.703+0100] {taskinstance.py:2076} INFO - Dependencies all met for dep_context=non-requeueable deps ti=<TaskInstance: churn_pipeline_taskflow.ingestion scheduled__2025-08-22T23:00:00+00:00 [queued]>
[2025-08-24T18:10:36.705+0100] {taskinstance.py:2076} INFO - Dependencies all met for dep_context=requeueable deps ti=<TaskInstance: churn_pipeline_taskflow.ingestion scheduled__2025-08-22T23:00:00+00:00 [queued]>
[2025-08-24T18:10:36.705+0100] {taskinstance.py:2306} INFO - Starting attempt 4 of 6
[2025-08-24T18:10:36.709+0100] {taskinstance.py:2330} INFO - Executing <Task(_PythonDecoratedOperator): ingestion> on 2025-08-22 23:00:00+00:00
[2025-08-24T18:10:36.711+0100] {standard_task_runner.py:64} INFO - Started process 26247 to run task
[2025-08-24T18:10:36.714+0100] {standard_task_runner.py:90} INFO - Running: ['airflow', 'tasks', 'run', 'churn_pipeline_taskflow', 'ingestion', 'scheduled__2025-08-22T23:00:00+00:00', '--job-id', '23', '--raw', '--subdir', 'DAGS_FOLDER/.ipynb_checkpoints/airflow_dag-checkpoint.py', '--cfg-path', '/var/folders/c_/hn2ql5p54ylf2dsc72vqg5h40000gn/T/tmplqmv121f']
[2025-08-24T18:10:36.715+0100] {standard_task_runner.py:91} INFO - Job 23: Subtask ingestion
[2025-08-24T18:10:36.729+0100] {task_command.py:426} INFO - Running <TaskInstance: churn_pipeline_taskflow.ingestion scheduled__2025-08-22T23:00:00+00:00 [running]> on host mac.communityfibre.co.uk
[2025-08-24T18:10:36.750+0100] {taskinstance.py:2648} INFO - Exporting env vars: AIRFLOW_CTX_DAG_OWNER='shivam' AIRFLOW_CTX_DAG_ID='churn_pipeline_taskflow' AIRFLOW_CTX_TASK_ID='ingestion' AIRFLOW_CTX_EXECUTION_DATE='2025-08-22T23:00:00+00:00' AIRFLOW_CTX_TRY_NUMBER='4' AIRFLOW_CTX_DAG_RUN_ID='scheduled__2025-08-22T23:00:00+00:00'
[2025-08-24T18:10:36.751+0100] {taskinstance.py:430} INFO - ::endgroup::
[2025-08-24T18:10:39.755+0100] {taskinstance.py:441} INFO - ::group::Post task execution logs
[2025-08-24T18:10:39.756+0100] {taskinstance.py:2905} ERROR - Task failed with exception
Traceback (most recent call last):
  File "/Users/homeaccount/miniconda3/envs/churn_pipeline/lib/python3.10/site-packages/airflow/models/taskinstance.py", line 465, in _execute_task
    result = _execute_callable(context=context, **execute_callable_kwargs)
  File "/Users/homeaccount/miniconda3/envs/churn_pipeline/lib/python3.10/site-packages/airflow/models/taskinstance.py", line 432, in _execute_callable
    return execute_callable(context=context, **execute_callable_kwargs)
  File "/Users/homeaccount/miniconda3/envs/churn_pipeline/lib/python3.10/site-packages/airflow/models/baseoperator.py", line 401, in wrapper
    return func(self, *args, **kwargs)
  File "/Users/homeaccount/miniconda3/envs/churn_pipeline/lib/python3.10/site-packages/airflow/decorators/base.py", line 265, in execute
    return_value = super().execute(context)
  File "/Users/homeaccount/miniconda3/envs/churn_pipeline/lib/python3.10/site-packages/airflow/models/baseoperator.py", line 401, in wrapper
    return func(self, *args, **kwargs)
  File "/Users/homeaccount/miniconda3/envs/churn_pipeline/lib/python3.10/site-packages/airflow/operators/python.py", line 235, in execute
    return_value = self.execute_callable()
  File "/Users/homeaccount/miniconda3/envs/churn_pipeline/lib/python3.10/site-packages/airflow/operators/python.py", line 252, in execute_callable
    return self.python_callable(*self.op_args, **self.op_kwargs)
  File "/Users/homeaccount/PycharmProjects/dmml/churn_prediction_pipeline/airflow_home/dags/.ipynb_checkpoints/airflow_dag-checkpoint.py", line 30, in ingestion
    run_cmd(["dvc", "add", "data/raw/telco_churn.csv", "data/raw/hf_bank_customer_support.csv"])
  File "/Users/homeaccount/PycharmProjects/dmml/churn_prediction_pipeline/airflow_home/dags/.ipynb_checkpoints/airflow_dag-checkpoint.py", line 16, in run_cmd
    subprocess.run(cmd, check=True)
  File "/Users/homeaccount/miniconda3/envs/churn_pipeline/lib/python3.10/subprocess.py", line 526, in run
    raise CalledProcessError(retcode, process.args,
subprocess.CalledProcessError: Command '['dvc', 'add', 'data/raw/telco_churn.csv', 'data/raw/hf_bank_customer_support.csv']' returned non-zero exit status 1.
[2025-08-24T18:10:39.759+0100] {taskinstance.py:1206} INFO - Marking task as UP_FOR_RETRY. dag_id=churn_pipeline_taskflow, task_id=ingestion, run_id=scheduled__2025-08-22T23:00:00+00:00, execution_date=20250822T230000, start_date=20250824T171036, end_date=20250824T171039
[2025-08-24T18:10:39.763+0100] {standard_task_runner.py:110} ERROR - Failed to execute job 23 for task ingestion (Command '['dvc', 'add', 'data/raw/telco_churn.csv', 'data/raw/hf_bank_customer_support.csv']' returned non-zero exit status 1.; 26247)
[2025-08-24T18:10:39.777+0100] {local_task_job_runner.py:243} INFO - Task exited with return code 1
[2025-08-24T18:10:39.784+0100] {taskinstance.py:3503} INFO - 0 downstream tasks scheduled from follow-on schedule check
[2025-08-24T18:10:39.784+0100] {local_task_job_runner.py:222} INFO - ::endgroup::
[2025-08-24T18:14:05.725+0100] {local_task_job_runner.py:120} INFO - ::group::Pre task execution logs
[2025-08-24T18:14:05.733+0100] {taskinstance.py:2076} INFO - Dependencies all met for dep_context=non-requeueable deps ti=<TaskInstance: churn_pipeline_taskflow.ingestion scheduled__2025-08-22T23:00:00+00:00 [queued]>
[2025-08-24T18:14:05.735+0100] {taskinstance.py:2076} INFO - Dependencies all met for dep_context=requeueable deps ti=<TaskInstance: churn_pipeline_taskflow.ingestion scheduled__2025-08-22T23:00:00+00:00 [queued]>
[2025-08-24T18:14:05.735+0100] {taskinstance.py:2306} INFO - Starting attempt 4 of 6
[2025-08-24T18:14:05.738+0100] {taskinstance.py:2330} INFO - Executing <Task(_PythonDecoratedOperator): ingestion> on 2025-08-22 23:00:00+00:00
[2025-08-24T18:14:05.740+0100] {standard_task_runner.py:64} INFO - Started process 26355 to run task
[2025-08-24T18:14:05.743+0100] {standard_task_runner.py:90} INFO - Running: ['airflow', 'tasks', 'run', 'churn_pipeline_taskflow', 'ingestion', 'scheduled__2025-08-22T23:00:00+00:00', '--job-id', '23', '--raw', '--subdir', 'DAGS_FOLDER/airflow_dag.py', '--cfg-path', '/var/folders/c_/hn2ql5p54ylf2dsc72vqg5h40000gn/T/tmp1u71aavp']
[2025-08-24T18:14:05.744+0100] {standard_task_runner.py:91} INFO - Job 23: Subtask ingestion
[2025-08-24T18:14:05.757+0100] {task_command.py:426} INFO - Running <TaskInstance: churn_pipeline_taskflow.ingestion scheduled__2025-08-22T23:00:00+00:00 [running]> on host mac.communityfibre.co.uk
[2025-08-24T18:14:05.777+0100] {taskinstance.py:2648} INFO - Exporting env vars: AIRFLOW_CTX_DAG_OWNER='shivam' AIRFLOW_CTX_DAG_ID='churn_pipeline_taskflow' AIRFLOW_CTX_TASK_ID='ingestion' AIRFLOW_CTX_EXECUTION_DATE='2025-08-22T23:00:00+00:00' AIRFLOW_CTX_TRY_NUMBER='4' AIRFLOW_CTX_DAG_RUN_ID='scheduled__2025-08-22T23:00:00+00:00'
[2025-08-24T18:14:05.777+0100] {taskinstance.py:430} INFO - ::endgroup::
[2025-08-24T18:14:05.777+0100] {logging_mixin.py:188} INFO - /Users/homeaccount/PycharmProjects/dmml/churn_prediction_pipeline
[2025-08-24T18:14:08.779+0100] {taskinstance.py:441} INFO - ::group::Post task execution logs
[2025-08-24T18:14:08.780+0100] {taskinstance.py:2905} ERROR - Task failed with exception
Traceback (most recent call last):
  File "/Users/homeaccount/miniconda3/envs/churn_pipeline/lib/python3.10/site-packages/airflow/models/taskinstance.py", line 465, in _execute_task
    result = _execute_callable(context=context, **execute_callable_kwargs)
  File "/Users/homeaccount/miniconda3/envs/churn_pipeline/lib/python3.10/site-packages/airflow/models/taskinstance.py", line 432, in _execute_callable
    return execute_callable(context=context, **execute_callable_kwargs)
  File "/Users/homeaccount/miniconda3/envs/churn_pipeline/lib/python3.10/site-packages/airflow/models/baseoperator.py", line 401, in wrapper
    return func(self, *args, **kwargs)
  File "/Users/homeaccount/miniconda3/envs/churn_pipeline/lib/python3.10/site-packages/airflow/decorators/base.py", line 265, in execute
    return_value = super().execute(context)
  File "/Users/homeaccount/miniconda3/envs/churn_pipeline/lib/python3.10/site-packages/airflow/models/baseoperator.py", line 401, in wrapper
    return func(self, *args, **kwargs)
  File "/Users/homeaccount/miniconda3/envs/churn_pipeline/lib/python3.10/site-packages/airflow/operators/python.py", line 235, in execute
    return_value = self.execute_callable()
  File "/Users/homeaccount/miniconda3/envs/churn_pipeline/lib/python3.10/site-packages/airflow/operators/python.py", line 252, in execute_callable
    return self.python_callable(*self.op_args, **self.op_kwargs)
  File "/Users/homeaccount/PycharmProjects/dmml/churn_prediction_pipeline/airflow_home/dags/airflow_dag.py", line 31, in ingestion
    run_cmd(["dvc", "add", "data/raw/telco_churn.csv", "data/raw/hf_bank_customer_support.csv"])
  File "/Users/homeaccount/PycharmProjects/dmml/churn_prediction_pipeline/airflow_home/dags/airflow_dag.py", line 16, in run_cmd
    subprocess.run(cmd, check=True)
  File "/Users/homeaccount/miniconda3/envs/churn_pipeline/lib/python3.10/subprocess.py", line 526, in run
    raise CalledProcessError(retcode, process.args,
subprocess.CalledProcessError: Command '['dvc', 'add', 'data/raw/telco_churn.csv', 'data/raw/hf_bank_customer_support.csv']' returned non-zero exit status 1.
[2025-08-24T18:14:08.784+0100] {taskinstance.py:1206} INFO - Marking task as UP_FOR_RETRY. dag_id=churn_pipeline_taskflow, task_id=ingestion, run_id=scheduled__2025-08-22T23:00:00+00:00, execution_date=20250822T230000, start_date=20250824T171405, end_date=20250824T171408
[2025-08-24T18:14:08.787+0100] {standard_task_runner.py:110} ERROR - Failed to execute job 23 for task ingestion (Command '['dvc', 'add', 'data/raw/telco_churn.csv', 'data/raw/hf_bank_customer_support.csv']' returned non-zero exit status 1.; 26355)
[2025-08-24T18:14:08.801+0100] {local_task_job_runner.py:243} INFO - Task exited with return code 1
[2025-08-24T18:14:08.809+0100] {taskinstance.py:3503} INFO - 0 downstream tasks scheduled from follow-on schedule check
[2025-08-24T18:14:08.809+0100] {local_task_job_runner.py:222} INFO - ::endgroup::
